Workbook

Sheet 2026
A1: Auftrags-ID | B1: Auftragsname | C1: Auftraggeber | D1: Abteilung | E1: Auftragstyp | F1: Sprache | G1: Wörter | H1: Stunden | I1: Dringend | J1: Kanal | K1: ID | L1: Eingang | M1: Lieferdatum | N1: Durchlaufzeit | O1: Deadline | P1: Eingehalten? | Q1: Translator | R1: Korrektur | S1: Verantwörtlich | T1: Status | U1: Ablageort | V1: Bemerkungen
B2: Übersetzung Januar newsletter NL.docx | C2: Pse | D2: =IF(_xlfn.XLOOKUP(C2, ABZ!A:A, ABZ!B:B, "", 0) = 0, "", _xlfn.XLOOKUP(C2, ABZ!A:A, ABZ!B:B, "", 0)) -> VTR-CS-SER-PartnerCommunication | E2: Übersetzung | F2: NL | G2: 68 | I2: =IF(AND(O2<>"",L2<>""),IF((O2-L2)<=2,1,0),0) -> 0 | L2: 46027 | M2: 46031 | N2: =IF(M2<>"",M2-L2,TODAY()-L2) -> 4 | O2: 46035 | P2: =IF(M2="","⏳ Offen",IF(M2<=O2,"✅ Ja","❌ Nein")) -> ✅ Ja | Q2: ADU | S2: MSI | T2: geliefert | U2: Z:\Produkte\FRITZ!com\deutsch\2026.01
B3: IT-Standalone-NL-2026.docx | C3: Jwg | D3: =IF(_xlfn.XLOOKUP(C3, ABZ!A:A, ABZ!B:B, "", 0) = 0, "", _xlfn.XLOOKUP(C3, ABZ!A:A, ABZ!B:B, "", 0)) -> VTR-CS-SER-PartnerCommunication | E3: Übersetzung | F3: IT | I3: =IF(AND(O3<>"",L3<>""),IF((O3-L3)<=2,1,0),0) -> 0 | L3: 46027 | M3: 46034 | N3: =IF(M3<>"",M3-L3,TODAY()-L3) -> 7 | O3: 46034 | P3: =IF(M3="","⏳ Offen",IF(M3<=O3,"✅ Ja","❌ Nein")) -> ✅ Ja | Q3: Cristina | R3: LBO | S3: MSI | T3: geliefert | U3: Z:\Produkte\FRITZ!com\deutsch\2026.01
B4: Information zu Speicherkrise 18122025.docx | C4: Dha | D4: =IF(_xlfn.XLOOKUP(C4, ABZ!A:A, ABZ!B:B, "", 0) = 0, "", _xlfn.XLOOKUP(C4, ABZ!A:A, ABZ!B:B, "", 0)) -> ENT-PM-International | E4: Übersetzung | F4: EN | I4: =IF(AND(O4<>"",L4<>""),IF((O4-L4)<=2,1,0),0) -> 1 | L4: 46027 | M4: 46028 | N4: =IF(M4<>"",M4-L4,TODAY()-L4) -> 1 | O4: 46028 | P4: =IF(M4="","⏳ Offen",IF(M4<=O4,"✅ Ja","❌ Nein")) -> ✅ Ja | Q4: JKI | S4: MSI | T4: geliefert | U4: Z:\Produkte\FRITZ!com\deutsch\2026.01
B5: Information zu Speicherkrise 18122025.docx | C5: Dha | D5: =IF(_xlfn.XLOOKUP(C5, ABZ!A:A, ABZ!B:B, "", 0) = 0, "", _xlfn.XLOOKUP(C5, ABZ!A:A, ABZ!B:B, "", 0)) -> ENT-PM-International | E5: Übersetzung | F5: IT | I5: =IF(AND(O5<>"",L5<>""),IF((O5-L5)<=2,1,0),0) -> 1 | L5: 46027 | M5: 46029 | N5: =IF(M5<>"",M5-L5,TODAY()-L5) -> 2 | O5: 46028 | P5: =IF(M5="","⏳ Offen",IF(M5<=O5,"✅ Ja","❌ Nein")) -> ❌ Nein | Q5: Cristin | R5: LBO | S5: MSI | T5: geliefert | U5: Z:\Produkte\FRITZ!com\deutsch\2026.01
B6: Information zu Speicherkrise 18122025.docx | C6: Dha | D6: =IF(_xlfn.XLOOKUP(C6, ABZ!A:A, ABZ!B:B, "", 0) = 0, "", _xlfn.XLOOKUP(C6, ABZ!A:A, ABZ!B:B, "", 0)) -> ENT-PM-International | E6: Übersetzung | F6: NL | I6: =IF(AND(O6<>"",L6<>""),IF((O6-L6)<=2,1,0),0) -> 1 | L6: 46027 | M6: 46029 | N6: =IF(M6<>"",M6-L6,TODAY()-L6) -> 2 | O6: 46028 | P6: =IF(M6="","⏳ Offen",IF(M6<=O6,"✅ Ja","❌ Nein")) -> ❌ Nein | Q6: Marion | R6: ADU | S6: MSI | T6: geliefert | U6: Z:\Produkte\FRITZ!com\deutsch\2026.01
B7: 2026-01-06T14-01-35_PM-History-Texts.xml | C7: TJa | D7: =IF(_xlfn.XLOOKUP(C7, ABZ!A:A, ABZ!B:B, "", 0) = 0, "", _xlfn.XLOOKUP(C7, ABZ!A:A, ABZ!B:B, "", 0)) -> ENT-PM-F-OS | E7: Lektorat | F7: DE | H7: 2 | I7: =IF(AND(O7<>"",L7<>""),IF((O7-L7)<=2,1,0),0) -> 1 | L7: 46027 | M7: 46027 | N7: =IF(M7<>"",M7-L7,TODAY()-L7) -> 0 | O7: 46027 | P7: =IF(M7="","⏳ Offen",IF(M7<=O7,"✅ Ja","❌ Nein")) -> ✅ Ja | Q7: FSC | S7: FSC | T7: geliefert | U7: Z:\Produkte\F!Box allgemein\Info.txt\Release\25_Smart24-P2\2026.01
B8: 2026-01-06T14-40-23_PM-History-Texts_korr-de.xml | C8: TJa | D8: =IF(_xlfn.XLOOKUP(C8, ABZ!A:A, ABZ!B:B, "", 0) = 0, "", _xlfn.XLOOKUP(C8, ABZ!A:A, ABZ!B:B, "", 0)) -> ENT-PM-F-OS | E8: Übersetzung | F8: EN | I8: =IF(AND(O8<>"",L8<>""),IF((O8-L8)<=2,1,0),0) -> 1 | L8: 46027 | M8: 46027 | N8: =IF(M8<>"",M8-L8,TODAY()-L8) -> 0 | O8: 46027 | P8: =IF(M8="","⏳ Offen",IF(M8<=O8,"✅ Ja","❌ Nein")) -> ✅ Ja | Q8: JKI | S8: FSC | T8: geliefert | U8: Z:\Produkte\F!Box allgemein\Info.txt\Release\25_Smart24-P2\2026.01
B9: Newsletter-IT-01-26.docx | C9: Jwg | D9: =IF(_xlfn.XLOOKUP(C9, ABZ!A:A, ABZ!B:B, "", 0) = 0, "", _xlfn.XLOOKUP(C9, ABZ!A:A, ABZ!B:B, "", 0)) -> VTR-CS-SER-PartnerCommunication | E9: Übersetzung | F9: IT | I9: =IF(AND(O9<>"",L9<>""),IF((O9-L9)<=2,1,0),0) -> 0 | L9: 46028 | M9: 46038 | N9: =IF(M9<>"",M9-L9,TODAY()-L9) -> 10 | O9: 46037 | P9: =IF(M9="","⏳ Offen",IF(M9<=O9,"✅ Ja","❌ Nein")) -> ❌ Nein | Q9: Cristin | R9: LBO | S9: HME | T9: geliefert | U9: Z:\Produkte\FRITZ!com\deutsch\2026.01
B10: Newsletter-ES-01-26.docx | C10: Jwg | D10: =IF(_xlfn.XLOOKUP(C10, ABZ!A:A, ABZ!B:B, "", 0) = 0, "", _xlfn.XLOOKUP(C10, ABZ!A:A, ABZ!B:B, "", 0)) -> VTR-CS-SER-PartnerCommunication | E10: Übersetzung | F10: ES | G10: 125 | I10: =IF(AND(O10<>"",L10<>""),IF((O10-L10)<=2,1,0),0) -> 0 | L10: 46028 | M10: 46038 | N10: =IF(M10<>"",M10-L10,TODAY()-L10) -> 10 | O10: 46037 | P10: =IF(M10="","⏳ Offen",IF(M10<=O10,"✅ Ja","❌ Nein")) -> ❌ Nein | Q10: AMZ | R10: HME | S10: HME | T10: geliefert | U10: Z:\Produkte\FRITZ!com\deutsch\2026.01
B11: METAFIELDS | C11: Csa | D11: =IF(_xlfn.XLOOKUP(C11, ABZ!A:A, ABZ!B:B, "", 0) = 0, "", _xlfn.XLOOKUP(C11, ABZ!A:A, ABZ!B:B, "", 0)) -> D2C-MarketingContent | E11: Übersetzung | F11: EN | I11: =IF(AND(O11<>"",L11<>""),IF((O11-L11)<=2,1,0),0) -> 0 | L11: 46028 | M11: 46030 | N11: =IF(M11<>"",M11-L11,TODAY()-L11) -> 2 | O11: 46034 | P11: =IF(M11="","⏳ Offen",IF(M11<=O11,"✅ Ja","❌ Nein")) -> ✅ Ja | Q11: JKI | S11: LBO | T11: geliefert | U11: Z:\Produkte\FRITZ!com\deutsch\2026.01\KW2
B12: METAFIELDS | C12: Csa | D12: =IF(_xlfn.XLOOKUP(C12, ABZ!A:A, ABZ!B:B, "", 0) = 0, "", _xlfn.XLOOKUP(C12, ABZ!A:A, ABZ!B:B, "", 0)) -> D2C-MarketingContent | E12: Übersetzung | F12: ES | I12: =IF(AND(O12<>"",L12<>""),IF((O12-L12)<=2,1,0),0) -> 0 | L12: 46028 | M12: 46029 | N12: =IF(M12<>"",M12-L12,TODAY()-L12) -> 1 | O12: 46034 | P12: =IF(M12="","⏳ Offen",IF(M12<=O12,"✅ Ja","❌ Nein")) -> ✅ Ja | Q12: HME | S12: LBO | T12: geliefert | U12: Z:\Produkte\FRITZ!com\deutsch\2026.01\KW2
B13: METAFIELDS | C13: Csa | D13: =IF(_xlfn.XLOOKUP(C13, ABZ!A:A, ABZ!B:B, "", 0) = 0, "", _xlfn.XLOOKUP(C13, ABZ!A:A, ABZ!B:B, "", 0)) -> D2C-MarketingContent | E13: Übersetzung | F13: FR | I13: =IF(AND(O13<>"",L13<>""),IF((O13-L13)<=2,1,0),0) -> 0 | L13: 46028 | M13: 46030 | N13: =IF(M13<>"",M13-L13,TODAY()-L13) -> 2 | O13: 46034 | P13: =IF(M13="","⏳ Offen",IF(M13<=O13,"✅ Ja","❌ Nein")) -> ✅ Ja | Q13: MSI | S13: LBO | T13: geliefert | U13: Z:\Produkte\FRITZ!com\deutsch\2026.01\KW2
B14: METAFIELDS | C14: Csa | D14: =IF(_xlfn.XLOOKUP(C14, ABZ!A:A, ABZ!B:B, "", 0) = 0, "", _xlfn.XLOOKUP(C14, ABZ!A:A, ABZ!B:B, "", 0)) -> D2C-MarketingContent | E14: Übersetzung | F14: IT | I14: =IF(AND(O14<>"",L14<>""),IF((O14-L14)<=2,1,0),0) -> 0 | L14: 46028 | M14: 46030 | N14: =IF(M14<>"",M14-L14,TODAY()-L14) -> 2 | O14: 46034 | P14: =IF(M14="","⏳ Offen",IF(M14<=O14,"✅ Ja","❌ Nein")) -> ✅ Ja | Q14: LBO | S14: LBO | T14: geliefert | U14: Z:\Produkte\FRITZ!com\deutsch\2026.01\KW2
B15: METAFIELDS | C15: Csa | D15: =IF(_xlfn.XLOOKUP(C15, ABZ!A:A, ABZ!B:B, "", 0) = 0, "", _xlfn.XLOOKUP(C15, ABZ!A:A, ABZ!B:B, "", 0)) -> D2C-MarketingContent | E15: Übersetzung | F15: NL | I15: =IF(AND(O15<>"",L15<>""),IF((O15-L15)<=2,1,0),0) -> 0 | L15: 46028 | M15: 46030 | N15: =IF(M15<>"",M15-L15,TODAY()-L15) -> 2 | O15: 46034 | P15: =IF(M15="","⏳ Offen",IF(M15<=O15,"✅ Ja","❌ Nein")) -> ✅ Ja | Q15: ADU | S15: LBO | T15: geliefert | U15: Z:\Produkte\FRITZ!com\deutsch\2026.01\KW2
B16: Data Act FRITZ!Smart-int-de.docx | C16: LLe | D16: =IF(_xlfn.XLOOKUP(C16, ABZ!A:A, ABZ!B:B, "", 0) = 0, "", _xlfn.XLOOKUP(C16, ABZ!A:A, ABZ!B:B, "", 0)) -> SUP-TCO-KnowledgeManagement | E16: Übersetzung | F16: DA | I16: =IF(AND(O16<>"",L16<>""),IF((O16-L16)<=2,1,0),0) -> 0 | J16: E-Mail | L16: 46029 | M16: 46036 | N16: =IF(M16<>"",M16-L16,TODAY()-L16) -> 7 | O16: 46052 | P16: =IF(M16="","⏳ Offen",IF(M16<=O16,"✅ Ja","❌ Nein")) -> ✅ Ja | Q16: Yabylon | S16: FSC | T16: geliefert | U16: Z:\Produkte\Einleger und juristische Texte\Data Act\FRITZ!Smart\2026.01
B17: Data Act FRITZ!Smart-int-de.docx | C17: LLe | D17: =IF(_xlfn.XLOOKUP(C17, ABZ!A:A, ABZ!B:B, "", 0) = 0, "", _xlfn.XLOOKUP(C17, ABZ!A:A, ABZ!B:B, "", 0)) -> SUP-TCO-KnowledgeManagement | E17: Übersetzung | F17: EN | I17: =IF(AND(O17<>"",L17<>""),IF((O17-L17)<=2,1,0),0) -> 0 | J17: E-Mail | L17: 46029 | M17: 46036 | N17: =IF(M17<>"",M17-L17,TODAY()-L17) -> 7 | O17: 46052 | P17: =IF(M17="","⏳ Offen",IF(M17<=O17,"✅ Ja","❌ Nein")) -> ✅ Ja | Q17: JKI | S17: FSC | T17: geliefert | U17: Z:\Produkte\Einleger und juristische Texte\Data Act\FRITZ!Smart\2026.01
B18: Data Act FRITZ!Smart-int-de.docx | C18: LLe | D18: =IF(_xlfn.XLOOKUP(C18, ABZ!A:A, ABZ!B:B, "", 0) = 0, "", _xlfn.XLOOKUP(C18, ABZ!A:A, ABZ!B:B, "", 0)) -> SUP-TCO-KnowledgeManagement | E18: Übersetzung | F18: ES | I18: =IF(AND(O18<>"",L18<>""),IF((O18-L18)<=2,1,0),0) -> 0 | J18: E-Mail | L18: 46029 | M18: 46036 | N18: =IF(M18<>"",M18-L18,TODAY()-L18) -> 7 | O18: 46052 | P18: =IF(M18="","⏳ Offen",IF(M18<=O18,"✅ Ja","❌ Nein")) -> ✅ Ja | Q18: AMZ | R18: HME | S18: FSC | T18: geliefert | U18: Z:\Produkte\Einleger und juristische Texte\Data Act\FRITZ!Smart\2026.01
B19: Data Act FRITZ!Smart-int-de.docx | C19: LLe | D19: =IF(_xlfn.XLOOKUP(C19, ABZ!A:A, ABZ!B:B, "", 0) = 0, "", _xlfn.XLOOKUP(C19, ABZ!A:A, ABZ!B:B, "", 0)) -> SUP-TCO-KnowledgeManagement | E19: Übersetzung | F19: FI | I19: =IF(AND(O19<>"",L19<>""),IF((O19-L19)<=2,1,0),0) -> 0 | J19: E-Mail | L19: 46029 | M19: 46036 | N19: =IF(M19<>"",M19-L19,TODAY()-L19) -> 7 | O19: 46052 | P19: =IF(M19="","⏳ Offen",IF(M19<=O19,"✅ Ja","❌ Nein")) -> ✅ Ja | Q19: Yabylon | S19: FSC | T19: geliefert | U19: Z:\Produkte\Einleger und juristische Texte\Data Act\FRITZ!Smart\2026.01
B20: Data Act FRITZ!Smart-int-de.docx | C20: LLe | D20: =IF(_xlfn.XLOOKUP(C20, ABZ!A:A, ABZ!B:B, "", 0) = 0, "", _xlfn.XLOOKUP(C20, ABZ!A:A, ABZ!B:B, "", 0)) -> SUP-TCO-KnowledgeManagement | E20: Übersetzung | F20: FR | I20: =IF(AND(O20<>"",L20<>""),IF((O20-L20)<=2,1,0),0) -> 0 | J20: E-Mail | L20: 46029 | M20: 46036 | N20: =IF(M20<>"",M20-L20,TODAY()-L20) -> 7 | O20: 46052 | P20: =IF(M20="","⏳ Offen",IF(M20<=O20,"✅ Ja","❌ Nein")) -> ✅ Ja | Q20: MSZ | S20: FSC | T20: geliefert | U20: Z:\Produkte\Einleger und juristische Texte\Data Act\FRITZ!Smart\2026.01
B21: Data Act FRITZ!Smart-int-de.docx | C21: LLe | D21: =IF(_xlfn.XLOOKUP(C21, ABZ!A:A, ABZ!B:B, "", 0) = 0, "", _xlfn.XLOOKUP(C21, ABZ!A:A, ABZ!B:B, "", 0)) -> SUP-TCO-KnowledgeManagement | E21: Übersetzung | F21: IT | I21: =IF(AND(O21<>"",L21<>""),IF((O21-L21)<=2,1,0),0) -> 0 | J21: E-Mail | L21: 46029 | M21: 46043 | N21: =IF(M21<>"",M21-L21,TODAY()-L21) -> 14 | O21: 46045 | P21: =IF(M21="","⏳ Offen",IF(M21<=O21,"✅ Ja","❌ Nein")) -> ✅ Ja | Q21: Cristin | R21: LBO | S21: FSC | T21: geliefert | U21: Z:\Produkte\Einleger und juristische Texte\Data Act\FRITZ!Smart\2026.01
B22: Data Act FRITZ!Smart-int-de.docx | C22: LLe | D22: =IF(_xlfn.XLOOKUP(C22, ABZ!A:A, ABZ!B:B, "", 0) = 0, "", _xlfn.XLOOKUP(C22, ABZ!A:A, ABZ!B:B, "", 0)) -> SUP-TCO-KnowledgeManagement | E22: Übersetzung | F22: NL | I22: =IF(AND(O22<>"",L22<>""),IF((O22-L22)<=2,1,0),0) -> 0 | J22: E-Mail | L22: 46029 | M22: 46038 | N22: =IF(M22<>"",M22-L22,TODAY()-L22) -> 9 | O22: 46045 | P22: =IF(M22="","⏳ Offen",IF(M22<=O22,"✅ Ja","❌ Nein")) -> ✅ Ja | Q22: ADU | S22: FSC | T22: geliefert | U22: Z:\Produkte\Einleger und juristische Texte\Data Act\FRITZ!Smart\2026.01
B23: Data Act FRITZ!Smart-int-de.docx | C23: LLe | D23: =IF(_xlfn.XLOOKUP(C23, ABZ!A:A, ABZ!B:B, "", 0) = 0, "", _xlfn.XLOOKUP(C23, ABZ!A:A, ABZ!B:B, "", 0)) -> SUP-TCO-KnowledgeManagement | E23: Übersetzung | F23: NO | I23: =IF(AND(O23<>"",L23<>""),IF((O23-L23)<=2,1,0),0) -> 0 | J23: E-Mail | L23: 46029 | M23: 46036 | N23: =IF(M23<>"",M23-L23,TODAY()-L23) -> 7 | O23: 46052 | P23: =IF(M23="","⏳ Offen",IF(M23<=O23,"✅ Ja","❌ Nein")) -> ✅ Ja | Q23: Yabylon | S23: FSC | T23: geliefert | U23: Z:\Produkte\Einleger und juristische Texte\Data Act\FRITZ!Smart\2026.01
B24: Data Act FRITZ!Smart-int-de.docx | C24: LLe | D24: =IF(_xlfn.XLOOKUP(C24, ABZ!A:A, ABZ!B:B, "", 0) = 0, "", _xlfn.XLOOKUP(C24, ABZ!A:A, ABZ!B:B, "", 0)) -> SUP-TCO-KnowledgeManagement | E24: Übersetzung | F24: PL | I24: =IF(AND(O24<>"",L24<>""),IF((O24-L24)<=2,1,0),0) -> 0 | J24: E-Mail | L24: 46029 | M24: 46036 | N24: =IF(M24<>"",M24-L24,TODAY()-L24) -> 7 | O24: 46052 | P24: =IF(M24="","⏳ Offen",IF(M24<=O24,"✅ Ja","❌ Nein")) -> ✅ Ja | Q24: Yabylon | S24: FSC | T24: geliefert | U24: Z:\Produkte\Einleger und juristische Texte\Data Act\FRITZ!Smart\2026.01
B25: Data Act FRITZ!Smart-int-de.docx | C25: LLe | D25: =IF(_xlfn.XLOOKUP(C25, ABZ!A:A, ABZ!B:B, "", 0) = 0, "", _xlfn.XLOOKUP(C25, ABZ!A:A, ABZ!B:B, "", 0)) -> SUP-TCO-KnowledgeManagement | E25: Übersetzung | F25: SV | I25: =IF(AND(O25<>"",L25<>""),IF((O25-L25)<=2,1,0),0) -> 0 | J25: E-Mail | L25: 46029 | M25: 46036 | N25: =IF(M25<>"",M25-L25,TODAY()-L25) -> 7 | O25: 46052 | P25: =IF(M25="","⏳ Offen",IF(M25<=O25,"✅ Ja","❌ Nein")) -> ✅ Ja | Q25: Yabylon | S25: FSC | T25: geliefert | U25: Z:\Produkte\Einleger und juristische Texte\Data Act\FRITZ!Smart\2026.01
B26: Data Act FRITZ!Smart-int-de.docx | C26: LLe | D26: =IF(_xlfn.XLOOKUP(C26, ABZ!A:A, ABZ!B:B, "", 0) = 0, "", _xlfn.XLOOKUP(C26, ABZ!A:A, ABZ!B:B, "", 0)) -> SUP-TCO-KnowledgeManagement | E26: Übersetzung | F26: SL | I26: =IF(AND(O26<>"",L26<>""),IF((O26-L26)<=2,1,0),0) -> 0 | J26: E-Mail | L26: 46029 | M26: 46036 | N26: =IF(M26<>"",M26-L26,TODAY()-L26) -> 7 | O26: 46052 | P26: =IF(M26="","⏳ Offen",IF(M26<=O26,"✅ Ja","❌ Nein")) -> ✅ Ja | Q26: Yabylon | S26: FSC | T26: geliefert | U26: Z:\Produkte\Einleger und juristische Texte\Data Act\FRITZ!Smart\2026.01
B27: Übersetzung Newsletter Solden-de.docx | C27: Atc | D27: =IF(_xlfn.XLOOKUP(C27, ABZ!A:A, ABZ!B:B, "", 0) = 0, "", _xlfn.XLOOKUP(C27, ABZ!A:A, ABZ!B:B, "", 0)) -> D2C-MarketingContent | E27: Übersetzung | F27: NL | I27: =IF(AND(O27<>"",L27<>""),IF((O27-L27)<=2,1,0),0) -> 1 | L27: 46029 | M27: 46034 | N27: =IF(M27<>"",M27-L27,TODAY()-L27) -> 5 | O27: 46031 | P27: =IF(M27="","⏳ Offen",IF(M27<=O27,"✅ Ja","❌ Nein")) -> ❌ Nein | Q27: ADU | S27: HME | T27: geliefert | U27: Z:\Produkte\FRITZ!com\deutsch\2026.01
B28: Übersetzung Abbinder Newsletter D2C_de.docx | C28: Atc | D28: =IF(_xlfn.XLOOKUP(C28, ABZ!A:A, ABZ!B:B, "", 0) = 0, "", _xlfn.XLOOKUP(C28, ABZ!A:A, ABZ!B:B, "", 0)) -> D2C-MarketingContent | E28: Übersetzung | F28: EN | I28: =IF(AND(O28<>"",L28<>""),IF((O28-L28)<=2,1,0),0) -> 0 | L28: 46029 | M28: 46036 | N28: =IF(M28<>"",M28-L28,TODAY()-L28) -> 7 | O28: 46036 | P28: =IF(M28="","⏳ Offen",IF(M28<=O28,"✅ Ja","❌ Nein")) -> ✅ Ja | Q28: JKI | S28: HME | T28: geliefert | U28: Z:\Produkte\FRITZ!com\deutsch\2026.01
B29: Übersetzung Abbinder Newsletter D2C_de.docx | C29: Atc | D29: =IF(_xlfn.XLOOKUP(C29, ABZ!A:A, ABZ!B:B, "", 0) = 0, "", _xlfn.XLOOKUP(C29, ABZ!A:A, ABZ!B:B, "", 0)) -> D2C-MarketingContent | E29: Übersetzung | F29: NL | I29: =IF(AND(O29<>"",L29<>""),IF((O29-L29)<=2,1,0),0) -> 0 | L29: 46029 | M29: 46036 | N29: =IF(M29<>"",M29-L29,TODAY()-L29) -> 7 | O29: 46036 | P29: =IF(M29="","⏳ Offen",IF(M29<=O29,"✅ Ja","❌ Nein")) -> ✅ Ja | Q29: ADU | S29: HME | T29: geliefert | U29: Z:\Produkte\FRITZ!com\deutsch\2026.01
B30: Übersetzung Abbinder Newsletter D2C_de.docx | C30: Atc | D30: =IF(_xlfn.XLOOKUP(C30, ABZ!A:A, ABZ!B:B, "", 0) = 0, "", _xlfn.XLOOKUP(C30, ABZ!A:A, ABZ!B:B, "", 0)) -> D2C-MarketingContent | E30: Übersetzung | F30: IT | I30: =IF(AND(O30<>"",L30<>""),IF((O30-L30)<=2,1,0),0) -> 0 | L30: 46029 | M30: 46036 | N30: =IF(M30<>"",M30-L30,TODAY()-L30) -> 7 | O30: 46036 | P30: =IF(M30="","⏳ Offen",IF(M30<=O30,"✅ Ja","❌ Nein")) -> ✅ Ja | Q30: LBO | S30: HME | T30: geliefert | U30: Z:\Produkte\FRITZ!com\deutsch\2026.01
B31: Übersetzung Abbinder Newsletter D2C_de.docx | C31: Atc | D31: =IF(_xlfn.XLOOKUP(C31, ABZ!A:A, ABZ!B:B, "", 0) = 0, "", _xlfn.XLOOKUP(C31, ABZ!A:A, ABZ!B:B, "", 0)) -> D2C-MarketingContent | E31: Übersetzung | F31: ES | I31: =IF(AND(O31<>"",L31<>""),IF((O31-L31)<=2,1,0),0) -> 0 | L31: 46029 | M31: 46036 | N31: =IF(M31<>"",M31-L31,TODAY()-L31) -> 7 | O31: 46036 | P31: =IF(M31="","⏳ Offen",IF(M31<=O31,"✅ Ja","❌ Nein")) -> ✅ Ja | Q31: AMZ | S31: HME | T31: geliefert | U31: Z:\Produkte\FRITZ!com\deutsch\2026.01
B32: Frohes neues Jahr 2026.docx | C32: Pse | D32: =IF(_xlfn.XLOOKUP(C32, ABZ!A:A, ABZ!B:B, "", 0) = 0, "", _xlfn.XLOOKUP(C32, ABZ!A:A, ABZ!B:B, "", 0)) -> VTR-CS-SER-PartnerCommunication | E32: Übersetzung | F32: NL | I32: =IF(AND(O32<>"",L32<>""),IF((O32-L32)<=2,1,0),0) -> 1 | L32: 46030 | M32: 46030 | N32: =IF(M32<>"",M32-L32,TODAY()-L32) -> 0 | O32: 46030 | P32: =IF(M32="","⏳ Offen",IF(M32<=O32,"✅ Ja","❌ Nein")) -> ✅ Ja | Q32: ADU | S32: MSI | T32: geliefert | U32: Z:\Produkte\FRITZ!com\deutsch\2026.01
B33: MyFapp_20260107-de.xml | C33: KSu | D33: =IF(_xlfn.XLOOKUP(C33, ABZ!A:A, ABZ!B:B, "", 0) = 0, "", _xlfn.XLOOKUP(C33, ABZ!A:A, ABZ!B:B, "", 0)) -> ENT-UIC-Android | E33: Übersetzung | F33: NL | G33: 256 | I33: =IF(AND(O33<>"",L33<>""),IF((O33-L33)<=2,1,0),0) -> 1 | J33: jazz | K33: 153535 | L33: 46029 | M33: 46030 | N33: =IF(M33<>"",M33-L33,TODAY()-L33) -> 1 | O33: 46030 | P33: =IF(M33="","⏳ Offen",IF(M33<=O33,"✅ Ja","❌ Nein")) -> ✅ Ja | Q33: CMI | R33: FSC | S33: FSC | T33: geliefert | U33: Z:\Produkte\F!Apps\FappMyF\GUI\Android\deutsch\2026.01
B34: MyFapp_20260107-de.xml | C34: KSu | D34: =IF(_xlfn.XLOOKUP(C34, ABZ!A:A, ABZ!B:B, "", 0) = 0, "", _xlfn.XLOOKUP(C34, ABZ!A:A, ABZ!B:B, "", 0)) -> ENT-UIC-Android | E34: Übersetzung | F34: EN | G34: 256 | I34: =IF(AND(O34<>"",L34<>""),IF((O34-L34)<=2,1,0),0) -> 0 | J34: jazz | K34: 153535 | L34: 46029 | M34: 46034 | N34: =IF(M34<>"",M34-L34,TODAY()-L34) -> 5 | O34: 46034 | P34: =IF(M34="","⏳ Offen",IF(M34<=O34,"✅ Ja","❌ Nein")) -> ✅ Ja | Q34: JKI | S34: FSC | T34: geliefert | U34: Z:\Produkte\F!Apps\FappMyF\GUI\Android\deutsch\2026.01
B35: MyFapp_20260107-de.xml | C35: KSu | D35: =IF(_xlfn.XLOOKUP(C35, ABZ!A:A, ABZ!B:B, "", 0) = 0, "", _xlfn.XLOOKUP(C35, ABZ!A:A, ABZ!B:B, "", 0)) -> ENT-UIC-Android | E35: Übersetzung | F35: NL | G35: 256 | I35: =IF(AND(O35<>"",L35<>""),IF((O35-L35)<=2,1,0),0) -> 0 | J35: jazz | K35: 153535 | L35: 46029 | M35: 46034 | N35: =IF(M35<>"",M35-L35,TODAY()-L35) -> 5 | O35: 46034 | P35: =IF(M35="","⏳ Offen",IF(M35<=O35,"✅ Ja","❌ Nein")) -> ✅ Ja | Q35: HME | S35: FSC | T35: geliefert | U35: Z:\Produkte\F!Apps\FappMyF\GUI\Android\deutsch\2026.01
B36: MyFapp_20260107-de.xml | C36: KSu | D36: =IF(_xlfn.XLOOKUP(C36, ABZ!A:A, ABZ!B:B, "", 0) = 0, "", _xlfn.XLOOKUP(C36, ABZ!A:A, ABZ!B:B, "", 0)) -> ENT-UIC-Android | E36: Übersetzung | F36: NL | G36: 256 | I36: =IF(AND(O36<>"",L36<>""),IF((O36-L36)<=2,1,0),0) -> 0 | J36: jazz | K36: 153535 | L36: 46029 | M36: 46034 | N36: =IF(M36<>"",M36-L36,TODAY()-L36) -> 5 | O36: 46034 | P36: =IF(M36="","⏳ Offen",IF(M36<=O36,"✅ Ja","❌ Nein")) -> ✅ Ja | Q36: MSZ | S36: FSC | T36: geliefert | U36: Z:\Produkte\F!Apps\FappMyF\GUI\Android\deutsch\2026.01
B37: MyFapp_20260107-de.xml | C37: KSu | D37: =IF(_xlfn.XLOOKUP(C37, ABZ!A:A, ABZ!B:B, "", 0) = 0, "", _xlfn.XLOOKUP(C37, ABZ!A:A, ABZ!B:B, "", 0)) -> ENT-UIC-Android | E37: Übersetzung | F37: IT | G37: 256 | I37: =IF(AND(O37<>"",L37<>""),IF((O37-L37)<=2,1,0),0) -> 0 | J37: jazz | K37: 153535 | L37: 46029 | M37: 46034 | N37: =IF(M37<>"",M37-L37,TODAY()-L37) -> 5 | O37: 46034 | P37: =IF(M37="","⏳ Offen",IF(M37<=O37,"✅ Ja","❌ Nein")) -> ✅ Ja | Q37: LBO | S37: FSC | T37: geliefert | U37: Z:\Produkte\F!Apps\FappMyF\GUI\Android\deutsch\2026.01
B38: MyFapp_20260107-de.xml | C38: KSu | D38: =IF(_xlfn.XLOOKUP(C38, ABZ!A:A, ABZ!B:B, "", 0) = 0, "", _xlfn.XLOOKUP(C38, ABZ!A:A, ABZ!B:B, "", 0)) -> ENT-UIC-Android | E38: Übersetzung | F38: NL | G38: 256 | I38: =IF(AND(O38<>"",L38<>""),IF((O38-L38)<=2,1,0),0) -> 0 | J38: jazz | K38: 153535 | L38: 46029 | M38: 46034 | N38: =IF(M38<>"",M38-L38,TODAY()-L38) -> 5 | O38: 46034 | P38: =IF(M38="","⏳ Offen",IF(M38<=O38,"✅ Ja","❌ Nein")) -> ✅ Ja | Q38: ADU | S38: FSC | T38: geliefert | U38: Z:\Produkte\F!Apps\FappMyF\GUI\Android\deutsch\2026.01
B39: MyFapp_20260107-de.xml | C39: KSu | D39: =IF(_xlfn.XLOOKUP(C39, ABZ!A:A, ABZ!B:B, "", 0) = 0, "", _xlfn.XLOOKUP(C39, ABZ!A:A, ABZ!B:B, "", 0)) -> ENT-UIC-Android | E39: Übersetzung | F39: PL | G39: 256 | I39: =IF(AND(O39<>"",L39<>""),IF((O39-L39)<=2,1,0),0) -> 0 | J39: jazz | K39: 153535 | L39: 46029 | M39: 46034 | N39: =IF(M39<>"",M39-L39,TODAY()-L39) -> 5 | O39: 46034 | P39: =IF(M39="","⏳ Offen",IF(M39<=O39,"✅ Ja","❌ Nein")) -> ✅ Ja | Q39: Yabylon | S39: FSC | T39: geliefert | U39: Z:\Produkte\F!Apps\FappMyF\GUI\Android\deutsch\2026.01
B40: MyFapp_20260107-de.xml | C40: KSu | D40: =IF(_xlfn.XLOOKUP(C40, ABZ!A:A, ABZ!B:B, "", 0) = 0, "", _xlfn.XLOOKUP(C40, ABZ!A:A, ABZ!B:B, "", 0)) -> ENT-UIC-Android | E40: Übersetzung | F40: SL | G40: 256 | I40: =IF(AND(O40<>"",L40<>""),IF((O40-L40)<=2,1,0),0) -> 0 | J40: jazz | K40: 153535 | L40: 46029 | M40: 46034 | N40: =IF(M40<>"",M40-L40,TODAY()-L40) -> 5 | O40: 46034 | P40: =IF(M40="","⏳ Offen",IF(M40<=O40,"✅ Ja","❌ Nein")) -> ✅ Ja | Q40: Yabylon | S40: FSC | T40: geliefert | U40: Z:\Produkte\F!Apps\FappMyF\GUI\Android\deutsch\2026.01
...

Sheet ABZ
A1: ADo | B1: ENT-Anwendungen
A2: AGi | B2: VTR-CS-SER-PartnerCommunication
A3: AKh | B3: KOM-Marketing
A4: ALb | B4: ENT-BA-GUI-Basis
A5: ALp | B5: KOM-PR
A6: ALe | B6: VTR-ChannelSales-CS
A7: APa | B7: VTR-CS-CM-Retail
A8: ASr | B8: VTR-PS-ProjectManagement
A9: ATc | B9: D2C-MarketingContent
A10: AZe | B10: ENT-WM-iOS-Apps
A11: AZi | B11: ENT-PM-F-Box
A12: Bal | B12: KOM-Marketing
... A124: EFH | B124: KOM-PR
