Workbook

Sheet 2025
A1: Aufträge | B1: Vom | C1: Sprache | D1: Verantwortlich | E1: Jazz | F1: Ablageort | G1: Datum | H1: Lieferung | I1: Deadline | J1: Abteilung | K1: Status
A3: API-Reference-de.docx | B3: TKO | C3: EN | D3: Joe | E3: Mail | F3: Z:\Produkte\Texte Web, Marketing, etc\deutsch\2025.01 | G3: 45660 | H3: 45664 | I3: 45665 | J3: =IF(_xlfn.XLOOKUP(B3, ABZ!A:A, ABZ!B:B, "", 0) = 0, "", _xlfn.XLOOKUP(B3, ABZ!A:A, ABZ!B:B, "", 0)) -> Technical Communication
A4: access-link-delivery-repeater-template_de.properties | B4: MxG | C4: EN | D4: Susan | E4: 137117 | F4: Z:\Produkte\MyFRITZ\deutsch\2024.12\MeshSetUebersetzung\Cloud-Mailing | G4: 45660 | H4: 45663 | I4: 45667 | J4: =IF(_xlfn.XLOOKUP(B4, ABZ!A:A, ABZ!B:B, "", 0) = 0, "", _xlfn.XLOOKUP(B4, ABZ!A:A, ABZ!B:B, "", 0)) -> CloudServices
A5: access-link-delivery-repeater-template_de.properties | B5: MxG | C5: ES | D5: Helena | E5: 137117 | F5: Z:\Produkte\MyFRITZ\deutsch\2024.12\MeshSetUebersetzung\Cloud-Mailing | G5: 45660 | H5: 45670 | I5: 45667 | J5: =IF(_xlfn.XLOOKUP(B5, ABZ!A:A, ABZ!B:B, "", 0) = 0, "", _xlfn.XLOOKUP(B5, ABZ!A:A, ABZ!B:B, "", 0)) -> CloudServices
A6: access-link-delivery-repeater-template_de.properties | B6: MxG | C6: FR | D6: Marie/Martine | E6: 137117 | F6: Z:\Produkte\MyFRITZ\deutsch\2024.12\MeshSetUebersetzung\Cloud-Mailing | G6: 45660 | H6: 45664 | I6: 45667 | J6: =IF(_xlfn.XLOOKUP(B6, ABZ!A:A, ABZ!B:B, "", 0) = 0, "", _xlfn.XLOOKUP(B6, ABZ!A:A, ABZ!B:B, "", 0)) -> CloudServices
A7: access-link-delivery-repeater-template_de.properties | B7: MxG | C7: IT | D7: Laura | E7: 137117 | F7: Z:\Produkte\MyFRITZ\deutsch\2024.12\MeshSetUebersetzung\Cloud-Mailing | G7: 45660 | H7: 45300 | I7: 45667 | J7: =IF(_xlfn.XLOOKUP(B7, ABZ!A:A, ABZ!B:B, "", 0) = 0, "", _xlfn.XLOOKUP(B7, ABZ!A:A, ABZ!B:B, "", 0)) -> CloudServices
A8: access-link-delivery-repeater-template_de.properties | B8: MxG | C8: NL | D8: Angelique | E8: 137117 | F8: Z:\Produkte\MyFRITZ\deutsch\2024.12\MeshSetUebersetzung\Cloud-Mailing | G8: 45660 | H8: 45666 | I8: 45667 | J8: =IF(_xlfn.XLOOKUP(B8, ABZ!A:A, ABZ!B:B, "", 0) = 0, "", _xlfn.XLOOKUP(B8, ABZ!A:A, ABZ!B:B, "", 0)) -> CloudServices
A9: botnet-detected-notification-repeater-template_de.properties | B9: MxG | C9: EN | D9: Susan | E9: 137117 | F9: Z:\Produkte\MyFRITZ\deutsch\2024.12\MeshSetUebersetzung\Cloud-Mailing | G9: 45660 | H9: 45663 | I9: 45667 | J9: =IF(_xlfn.XLOOKUP(B9, ABZ!A:A, ABZ!B:B, "", 0) = 0, "", _xlfn.XLOOKUP(B9, ABZ!A:A, ABZ!B:B, "", 0)) -> CloudServices
A10: botnet-detected-notification-repeater-template_de.properties | B10: MxG | C10: ES | D10: Helena | E10: 137117 | F10: Z:\Produkte\MyFRITZ\deutsch\2024.12\MeshSetUebersetzung\Cloud-Mailing | G10: 45660 | H10: 45670 | I10: 45667 | J10: =IF(_xlfn.XLOOKUP(B10, ABZ!A:A, ABZ!B:B, "", 0) = 0, "", _xlfn.XLOOKUP(B10, ABZ!A:A, ABZ!B:B, "", 0)) -> CloudServices
A11: botnet-detected-notification-repeater-template_de.properties | B11: MxG | C11: FR | D11: Marie/Martine | E11: 137117 | F11: Z:\Produkte\MyFRITZ\deutsch\2024.12\MeshSetUebersetzung\Cloud-Mailing | G11: 45660 | H11: 45664 | I11: 45667 | J11: =IF(_xlfn.XLOOKUP(B11, ABZ!A:A, ABZ!B:B, "", 0) = 0, "", _xlfn.XLOOKUP(B11, ABZ!A:A, ABZ!B:B, "", 0)) -> CloudServices
A12: botnet-detected-notification-repeater-template_de.properties | B12: MxG | C12: IT | D12: Laura | E12: 137117 | F12: Z:\Produkte\MyFRITZ\deutsch\2024.12\MeshSetUebersetzung\Cloud-Mailing | G12: 45660 | H12: 45300 | I12: 45667 | J12: =IF(_xlfn.XLOOKUP(B12, ABZ!A:A, ABZ!B:B, "", 0) = 0, "", _xlfn.XLOOKUP(B12, ABZ!A:A, ABZ!B:B, "", 0)) -> CloudServices
A13: botnet-detected-notification-repeater-template_de.properties | B13: MxG | C13: NL | D13: Angelique | E13: 137117 | F13: Z:\Produkte\MyFRITZ\deutsch\2024.12\MeshSetUebersetzung\Cloud-Mailing | G13: 45660 | H13: 45666 | I13: 45667 | J13: =IF(_xlfn.XLOOKUP(B13, ABZ!A:A, ABZ!B:B, "", 0) = 0, "", _xlfn.XLOOKUP(B13, ABZ!A:A, ABZ!B:B, "", 0)) -> CloudServices
A14: confirm-box-repeater_de.properties | B14: MxG | C14: EN | D14: Susan | E14: 137117 | F14: Z:\Produkte\MyFRITZ\deutsch\2024.12\MeshSetUebersetzung\Box-Management | G14: 45660 | H14: 45663 | I14: 45667 | J14: =IF(_xlfn.XLOOKUP(B14, ABZ!A:A, ABZ!B:B, "", 0) = 0, "", _xlfn.XLOOKUP(B14, ABZ!A:A, ABZ!B:B, "", 0)) -> CloudServices
A15: confirm-box-repeater_de.properties | B15: MxG | C15: ES | D15: Helena | E15: 137117 | F15: Z:\Produkte\MyFRITZ\deutsch\2024.12\MeshSetUebersetzung\Box-Management | G15: 45660 | H15: 45670 | I15: 45667 | J15: =IF(_xlfn.XLOOKUP(B15, ABZ!A:A, ABZ!B:B, "", 0) = 0, "", _xlfn.XLOOKUP(B15, ABZ!A:A, ABZ!B:B, "", 0)) -> CloudServices
... A83: update-succeeded-notification-repeater-template_de.properties | B83: MxG | C83: NL | D83: Angelique | E83: 137117 | F83: Z:\Produkte\MyFRITZ\deutsch\2024.12\MeshSetUebersetzung\Cloud-Mailing | G83: 45660 | H83: 45666 | I83: 45667 | J83: =IF(_xlfn.XLOOKUP(B83, ABZ!A:A, ABZ!B:B, "", 0) = 0, "", _xlfn.XLOOKUP(B83, ABZ!A:A, ABZ!B:B, "", 0)) -> CloudServices
A85: Gewinnerbenachrichtigung-Du-Form-de.docx | B85: Pse | C85: NL | D85: Angelique | F85: Z:\Produkte\Texte Web, Marketing, etc\deutsch\2025.01 | G85: 45665 | H85: 45667 | J85: =IF(_xlfn.XLOOKUP(B85, ABZ!A:A, ABZ!B:B, "", 0) = 0, "", _xlfn.XLOOKUP(B85, ABZ!A:A, ABZ!B:B, "", 0)) -> Channel Sales
A86: Gewinnerbenachrichtigung-Du-Form-de.docx | B86: Pse | C86: ES | D86: Marta/Helena | F86: Z:\Produkte\Texte Web, Marketing, etc\deutsch\2025.01 | G86: 45665 | H86: 45667 | J86: =IF(_xlfn.XLOOKUP(B86, ABZ!A:A, ABZ!B:B, "", 0) = 0, "", _xlfn.XLOOKUP(B86, ABZ!A:A, ABZ!B:B, "", 0)) -> Channel Sales
A87: Gewinnerbenachrichtigung-Du-Form-de.docx | B87: Pse | C87: IT | D87: Crisitna/Laura | F87: Z:\Produkte\Texte Web, Marketing, etc\deutsch\2025.01 | G87: 45665 | H87: 45301 | J87: =IF(_xlfn.XLOOKUP(B87, ABZ!A:A, ABZ!B:B, "", 0) = 0, "", _xlfn.XLOOKUP(B87, ABZ!A:A, ABZ!B:B, "", 0)) -> Channel Sales
A88: Newsletter ES Jan25.docx | B88: Jwg | C88: ES | D88: Marta/Helena | F88: Z:\Produkte\Texte Web, Marketing, etc\deutsch\2025.01 | G88: 45665 | H88: 45670 | I88: 45671 | J88: =IF(_xlfn.XLOOKUP(B88, ABZ!A:A, ABZ!B:B, "", 0) = 0, "", _xlfn.XLOOKUP(B88, ABZ!A:A, ABZ!B:B, "", 0)) -> Channel Sales
A89: FR_Amazon_Brand_Store_Texte_Übersetzungsbüro.docx | B89: apa | C89: FR | D89: Marie | F89: Z:\Produkte\Texte Web, Marketing, etc\deutsch\2025.01 | G89: 45666 | H89: 45674 | I89: 45672 | J89: =IF(_xlfn.XLOOKUP(B89, ABZ!A:A, ABZ!B:B, "", 0) = 0, "", _xlfn.XLOOKUP(B89, ABZ!A:A, ABZ!B:B, "", 0)) -> Sales Marketing
A90: 20241203_Provider International Pitch_1-16-de.pptx | B90: PWI | C90: EN | D90: Susan | F90: Z:\Produkte\Texte Web, Marketing, etc\deutsch\2025.01 | G90: 45667 | H90: 45670 | I90: 45671 | J90: =IF(_xlfn.XLOOKUP(B90, ABZ!A:A, ABZ!B:B, "", 0) = 0, "", _xlfn.XLOOKUP(B90, ABZ!A:A, ABZ!B:B, "", 0)) -> Sales Marketing
A91: Mesh Set 3000_[DE-Vorlage].idml | B91: Ost | C91: EN | D91: Susan | F91: Z:\Produkte\F!WLAN Repeater\Mesh Set 3000 (1200 AX)\international\2025.01\UeM | G91: 45667 | H91: 45670 | I91: 45672 | J91: =IF(_xlfn.XLOOKUP(B91, ABZ!A:A, ABZ!B:B, "", 0) = 0, "", _xlfn.XLOOKUP(B91, ABZ!A:A, ABZ!B:B, "", 0)) -> Technical Communication
A92: Mesh Set 3000_[DE-Vorlage].idml | B92: Ost | C92: FR | D92: Marie | F92: Z:\Produkte\F!WLAN Repeater\Mesh Set 3000 (1200 AX)\international\2025.01\UeM | G92: 45667 | H92: 45670 | I92: 45672 | J92: =IF(_xlfn.XLOOKUP(B92, ABZ!A:A, ABZ!B:B, "", 0) = 0, "", _xlfn.XLOOKUP(B92, ABZ!A:A, ABZ!B:B, "", 0)) -> Technical Communication
A93: Mesh Set 3000_[DE-Vorlage].idml | B93: Ost | C93: ES | D93: Helena | F93: Z:\Produkte\F!WLAN Repeater\Mesh Set 3000 (1200 AX)\international\2025.01\UeM | G93: 45667 | H93: 45672 | I93: 45672 | J93: =IF(_xlfn.XLOOKUP(B93, ABZ!A:A, ABZ!B:B, "", 0) = 0, "", _xlfn.XLOOKUP(B93, ABZ!A:A, ABZ!B:B, "", 0)) -> Technical Communication
A94: Mesh Set 3000_[DE-Vorlage].idml | B94: Ost | C94: IT | D94: Laura | F94: Z:\Produkte\F!WLAN Repeater\Mesh Set 3000 (1200 AX)\international\2025.01\UeM | G94: 45667 | H94: 45670 | I94: 45672 | J94: =IF(_xlfn.XLOOKUP(B94, ABZ!A:A, ABZ!B:B, "", 0) = 0, "", _xlfn.XLOOKUP(B94, ABZ!A:A, ABZ!B:B, "", 0)) -> Technical Communication
A95: Mesh Set 3000_[DE-Vorlage].idml | B95: Ost | C95: NL | D95: Angelique | F95: Z:\Produkte\F!WLAN Repeater\Mesh Set 3000 (1200 AX)\international\2025.01\UeM | G95: 45667 | H95: 45672 | I95: 45672 | J95: =IF(_xlfn.XLOOKUP(B95, ABZ!A:A, ABZ!B:B, "", 0) = 0, "", _xlfn.XLOOKUP(B95, ABZ!A:A, ABZ!B:B, "", 0)) -> Technical Communication
A96: Master_HB_Frep_MeshSet_V4-2025-01-10_D-00000082_T-00000762_EngineeringModules_de-DE_en-US.xml | B96: Cmi | C96: EN | D96: Susan | E96: Mail | F96: Z:\International\Tico\work\2025-01-10_D-00000082_T-00000762_de-DE_en-US.xml\untranslated | G96: 45667 | H96: 45670 | I96: 45684 | J96: =IF(_xlfn.XLOOKUP(B96, ABZ!A:A, ABZ!B:B, "", 0) = 0, "", _xlfn.XLOOKUP(B96, ABZ!A:A, ABZ!B:B, "", 0)) -> Technical Communication
A97: Master_HB_Frep_MeshSet_V4-2025-01-10_D-00000082_T-00000765_EngineeringModules_de-DE_it-IT.Fragments.xml | B97: Cmi | C97: IT | D97: Laura | E97: Mail | F97: Z:\International\Tico\work\2025-01-10_D-00000082_T-00000765_de-DE_it-IT.xml\untranslated | G97: 45667 | H97: 45686 | I97: 45684 | J97: =IF(_xlfn.XLOOKUP(B97, ABZ!A:A, ABZ!B:B, "", 0) = 0, "", _xlfn.XLOOKUP(B97, ABZ!A:A, ABZ!B:B, "", 0)) -> Technical Communication
A98: Master_HB_Frep_MeshSet_V4-2025-01-10_D-00000082_T-00000765_EngineeringModules_de-DE_it-IT.xml | B98: Cmi | C98: IT | D98: Laura | E98: Mail | F98: Z:\International\Tico\work\2025-01-10_D-00000082_T-00000765_de-DE_it-IT.xml\untranslated | G98: 45667 | H98: 45686 | I98: 45684 | J98: =IF(_xlfn.XLOOKUP(B98, ABZ!A:A, ABZ!B:B, "", 0) = 0, "", _xlfn.XLOOKUP(B98, ABZ!A:A, ABZ!B:B, "", 0)) -> Technical Communication
A99: Master_HB_Frep_MeshSet_V4-2025-01-10_D-00000082_T-00000764_EngineeringModules_de-DE_es-ES.xml | B99: Cmi | C99: ES | D99: Helena | E99: Mail | F99: Z:\International\Tico\work\2025-01-10_D-00000082_T-00000764_de-DE_es-ES.xml\untranslated | G99: 45667 | H99: 45684 | I99: 45684 | J99: =IF(_xlfn.XLOOKUP(B99, ABZ!A:A, ABZ!B:B, "", 0) = 0, "", _xlfn.XLOOKUP(B99, ABZ!A:A, ABZ!B:B, "", 0)) -> Technical Communication
A100: Master_HB_Frep_MeshSet_V4-2025-01-10_D-00000082_T-00000763_EngineeringModules_de-DE_fr-FR.xml | B100: Cmi | C100: FR | D100: Martine | E100: Mail | F100: Z:\International\Tico\work\2025-01-10_D-00000082_T-00000763_de-DE_fr-FR.xml\untranslated | G100: 45667 | H100: 45670 | I100: 45684 | J100: =IF(_xlfn.XLOOKUP(B100, ABZ!A:A, ABZ!B:B, "", 0) = 0, "", _xlfn.XLOOKUP(B100, ABZ!A:A, ABZ!B:B, "", 0)) -> Technical Communication
A101: Master_HB_Frep_MeshSet_V4-2025-01-10_D-00000082_T-00000766_EngineeringModules_de-DE_nl-NL.xml | B101: Cmi | C101: NL | D101: Angelique | E101: Mail | F101: Z:\International\Tico\work\2025-01-10_D-00000082_T-00000766_de-DE_nl-NL.xml\untranslated | G101: 45667 | H101: 45672 | I101: 45684 | J101: =IF(_xlfn.XLOOKUP(B101, ABZ!A:A, ABZ!B:B, "", 0) = 0, "", _xlfn.XLOOKUP(B101, ABZ!A:A, ABZ!B:B, "", 0)) -> Technical Communication
A102: Newsletter 01_2025-de-nl.docx | B102: PSe | C102: DE | D102: Franziska | E102: Mail | F102: Z:\Produkte\Texte Web, Marketing, etc\deutsch\2025.01 | G102: 45670 | H102: 45670 | I102: 45670 | J102: =IF(_xlfn.XLOOKUP(B102, ABZ!A:A, ABZ!B:B, "", 0) = 0, "", _xlfn.XLOOKUP(B102, ABZ!A:A, ABZ!B:B, "", 0)) -> Channel Sales
A103: Newsletter 01_2025-de-nl.docx | B103: PSe | C103: NL | D103: Angelique | E103: Mail | F103: Z:\Produkte\Texte Web, Marketing, etc\deutsch\2025.01 | G103: 45670 | H103: 45670 | I103: 45670 | J103: =IF(_xlfn.XLOOKUP(B103, ABZ!A:A, ABZ!B:B, "", 0) = 0, "", _xlfn.XLOOKUP(B103, ABZ!A:A, ABZ!B:B, "", 0)) -> Channel Sales
A104: Januar-Newsletter Österreich | B104: PSe | C104: DE | D104: Franziska | E104: Mail | G104: 45670 | H104: 45670 | I104: 45670 | J104: =IF(_xlfn.XLOOKUP(B104, ABZ!A:A, ABZ!B:B, "", 0) = 0, "", _xlfn.XLOOKUP(B104, ABZ!A:A, ABZ!B:B, "", 0)) -> Channel Sales
A105: Januar-Newsletter Schweiz | B105: PSe | C105: DE | D105: Franziska | E105: Mail | G105: 45670 | H105: 45670 | I105: 45670 | J105: =IF(_xlfn.XLOOKUP(B105, ABZ!A:A, ABZ!B:B, "", 0) = 0, "", _xlfn.XLOOKUP(B105, ABZ!A:A, ABZ!B:B, "", 0)) -> Channel Sales
A106: Kick-off_2025-de-en.docx | B106: AGi | C106: DE | D106: Franziska | E106: Mail | F106: Z:\Produkte\Texte Web, Marketing, etc\deutsch\2025.01 | G106: 45671 | H106: 45671 | I106: 45671 | J106: =IF(_xlfn.XLOOKUP(B106, ABZ!A:A, ABZ!B:B, "", 0) = 0, "", _xlfn.XLOOKUP(B106, ABZ!A:A, ABZ!B:B, "", 0)) -> Channel Sales
A107: Kick-off_2025-de-en.docx | B107: AGi | C107: EN | D107: Susan | E107: Mail | F107: Z:\Produkte\Texte Web, Marketing, etc\deutsch\2025.01 | G107: 45671 | H107: 45671 | I107: 45671 | J107: =IF(_xlfn.XLOOKUP(B107, ABZ!A:A, ABZ!B:B, "", 0) = 0, "", _xlfn.XLOOKUP(B107, ABZ!A:A, ABZ!B:B, "", 0)) -> Channel Sales
A108: Master_OLH_F!MeshSet_v3-2025-01-14_D-00000080_T-00000770_EngineeringModules_de-DE_it-IT.xml | B108: Cmi | C108: IT | D108: Laura | E108: Mail | F108: Z:\International\Tico\work\2025-01-14_D-00000080_T-00000770_de-DE_it-IT.xml\untranslated | G108: 45671 | H108: 45688 | I108: 45680 | J108: =IF(_xlfn.XLOOKUP(B108, ABZ!A:A, ABZ!B:B, "", 0) = 0, "", _xlfn.XLOOKUP(B108, ABZ!A:A, ABZ!B:B, "", 0)) -> Technical Communication
A109: Master_OLH_F!MeshSet_v3-2025-01-14_D-00000080_T-00000771_EngineeringModules_de-DE_nl-NL.xml | B109: Cmi | C109: NL | D109: Angelique | E109: Mail | F109: Z:\International\Tico\work\2025-01-14_D-00000080_T-00000771_de-DE_nl-NL.xml\untranslated | G109: 45671 | H109: 45680 | I109: 45680 | J109: =IF(_xlfn.XLOOKUP(B109, ABZ!A:A, ABZ!B:B, "", 0) = 0, "", _xlfn.XLOOKUP(B109, ABZ!A:A, ABZ!B:B, "", 0)) -> Technical Communication
...

Sheet ABZ
A1: ADo | B1: User Interface & Clients
A2: AGi | B2: Channel Sales
A3: AKh | B3: Corporate Communications
A4: ALb | B4: User Interface & Clients
A5: ALp | B5: Corporate Communications
A6: ALe | B6: Channel Sales
A7: ALi | B7: Finance
A8: APa | B8: Sales Marketing
A9: ASr | B9: Provider Sales
A10: ATc | B10: D2C Ecommerce
A11: AZe | B11: User Interface & Clients
A12: AZi | B12: Product Management
... A127: Csa | B127: D2C Ecommerce
