Workbook

Sheet 2026
A1: Spalte1 | B1: Wörter | C1: Zeit | D1: Von | E1: Sprache | F1: Übersetzung | G1: Korrektur | H1: Kanal | I1: Eingang | J1: Lieferdatum | K1: Deadline | L1: Abteilung | M1: Status | N1: Verantwortlich | O1: Ablageort | P1: Bereich
A2: 2026-02-03T14-17-44_PM-History-Texts.xml | D2: TJa | E2: DE | G2: Franziska | H2: LS-Tracker | I2: 45993 | J2: 46026 | K2: 46056 | L2: =IF(_xlfn.XLOOKUP(D2, ABZ!A:A, ABZ!B:B, "", 0) = 0, "", _xlfn.XLOOKUP(D2, ABZ!A:A, ABZ!B:B, "", 0)) -> Product Management | M2: geliefert | N2: FSc | O2: Z:\Produkte\F!Box allgemein\Info.txt\Release\25_Smart24-P2\2026.02 | P2: Vertrieb
A3: 2026-02-03T15-55-13_PM-History-Texts_korr-de.xml | D3: TJa | E3: EN | F3: Franziska | H3: LS-Tracker | I3: 45691 | J3: 46056 | K3: 46056 | L3: =IF(_xlfn.XLOOKUP(D3, ABZ!A:A, ABZ!B:B, "", 0) = 0, "", _xlfn.XLOOKUP(D3, ABZ!A:A, ABZ!B:B, "", 0)) -> Product Management | M3: geliefert | O3: Z:\Produkte\F!Box allgemein\Info.txt\Release\25_Smart24-P2\2026.02 | P3: Vertrieb
A4: 2026_Ankuendigung_FRITZ!Repeater_2400_Edition International-de.docx | B4: 503 | D4: APa | E4: DE | H4: Mail | I4: 45701 | J4: 46069 | K4: 46073 | L4: =IF(_xlfn.XLOOKUP(D4, ABZ!A:A, ABZ!B:B, "", 0) = 0, "", _xlfn.XLOOKUP(D4, ABZ!A:A, ABZ!B:B, "", 0)) -> Sales Marketing | M4: Ü-fertig | N4: Hme | O4: Z:\Produkte\Texte Web, Marketing, etc\deutsch\2026.02 | P4: Entwicklung
A5: 2026_Ankuendigung_FRITZ!Repeater_2400_Edition International-de.docx | B5: 503 | D5: APa | E5: PL | F5: Yabylon | H5: Mail | I5: 45701 | J5: 46069 | K5: 46073 | L5: =IF(_xlfn.XLOOKUP(D5, ABZ!A:A, ABZ!B:B, "", 0) = 0, "", _xlfn.XLOOKUP(D5, ABZ!A:A, ABZ!B:B, "", 0)) -> Sales Marketing | M5: geliefert | N5: Hme | O5: Z:\Produkte\Texte Web, Marketing, etc\deutsch\2026.02 | P5: Entwicklung
A6: 2026_Ankuendigung_FRITZ!Repeater 600 Edition International-de.docx | B6: 443 | D6: APa | E6: DE | H6: Mail | I6: 45701 | J6: 46069 | K6: 46073 | L6: =IF(_xlfn.XLOOKUP(D6, ABZ!A:A, ABZ!B:B, "", 0) = 0, "", _xlfn.XLOOKUP(D6, ABZ!A:A, ABZ!B:B, "", 0)) -> Sales Marketing | M6: Ü-fertig | N6: Hme | O6: Z:\Produkte\Texte Web, Marketing, etc\deutsch\2026.02 | P6: Entwicklung
A7: 2026_Ankuendigung_FRITZ!Repeater 600 Edition International-de.docx | B7: 443 | D7: APa | E7: Pl | F7: Yabylon | H7: Mail | I7: 45701 | J7: 46069 | K7: 46073 | L7: =IF(_xlfn.XLOOKUP(D7, ABZ!A:A, ABZ!B:B, "", 0) = 0, "", _xlfn.XLOOKUP(D7, ABZ!A:A, ABZ!B:B, "", 0)) -> Sales Marketing | M7: geliefert | N7: Hme | O7: Z:\Produkte\Texte Web, Marketing, etc\deutsch\2026.02 | P7: Entwicklung
A8: NL_Newsletter_März.docx | B8: 514 | D8: Pse | E8: NL | F8: Angelique | H8: LS-Tracker | I8: 45720 | J8: 46091 | K8: 46094 | L8: =IF(_xlfn.XLOOKUP(D8, ABZ!A:A, ABZ!B:B, "", 0) = 0, "", _xlfn.XLOOKUP(D8, ABZ!A:A, ABZ!B:B, "", 0)) -> Channel Sales | M8: geliefert | N8: Hme | O8: BP-Technik | P8: Entwicklung
A9: 4614_en-GB_technik_20260304-092633.xml | B9: 367 | D9: Pse | E9: EN | F9: John | H9: LS-Tracker | I9: 45720 | J9: 46101 | K9: 46101 | L9: =IF(_xlfn.XLOOKUP(D9, ABZ!A:A, ABZ!B:B, "", 0) = 0, "", _xlfn.XLOOKUP(D9, ABZ!A:A, ABZ!B:B, "", 0)) -> Channel Sales | M9: geliefert | N9: Hme | O9: BP-Technik | P9: Vertrieb
A10: 4746_en-GB_security_und_software_20260304-091506.xml | B10: 104 | D10: Pse | E10: EN | F10: John | H10: LS-Tracker | I10: 45720 | J10: 46101 | K10: 46101 | L10: =IF(_xlfn.XLOOKUP(D10, ABZ!A:A, ABZ!B:B, "", 0) = 0, "", _xlfn.XLOOKUP(D10, ABZ!A:A, ABZ!B:B, "", 0)) -> Channel Sales | M10: geliefert | N10: Hme | O10: BP-Technik | P10: Vertrieb
A11: 4747_en-GB_failsafe_20260304-091557.xml | B11: 295 | D11: Pse | E11: EN | F11: John | H11: LS-Tracker | I11: 45720 | J11: 46101 | K11: 46101 | L11: =IF(_xlfn.XLOOKUP(D11, ABZ!A:A, ABZ!B:B, "", 0) = 0, "", _xlfn.XLOOKUP(D11, ABZ!A:A, ABZ!B:B, "", 0)) -> Channel Sales | M11: geliefert | N11: Hme | O11: BP-Technik | P11: D2C
A12: 4748_en-GB_fritz_wissensdatenbank_20260304-091553.xml | B12: 277 | D12: Pse | E12: EN | F12: John | H12: LS-Tracker | I12: 45720 | J12: 46101 | K12: 46101 | L12: =IF(_xlfn.XLOOKUP(D12, ABZ!A:A, ABZ!B:B, "", 0) = 0, "", _xlfn.XLOOKUP(D12, ABZ!A:A, ABZ!B:B, "", 0)) -> Channel Sales | M12: geliefert | N12: Hme | O12: BP-Technik | P12: D2C
A13: 4749_en-GB_upload_freigabe_fuer_einfachen_dateiaustausch_20260304-091549.xml | B13: 409 | D13: Pse | E13: EN | F13: John | H13: LS-Tracker | I13: 45720 | J13: 46101 | K13: 46101 | L13: =IF(_xlfn.XLOOKUP(D13, ABZ!A:A, ABZ!B:B, "", 0) = 0, "", _xlfn.XLOOKUP(D13, ABZ!A:A, ABZ!B:B, "", 0)) -> Channel Sales | M13: geliefert | N13: Hme | O13: BP-Technik | P13: D2C
A14: 4750_en-GB_wi_fi_7_das_multi_gigabit_wlan_ist_da_20260304-091544.xml | B14: 526 | D14: Pse | E14: EN | F14: Lisa | H14: LS-Tracker | I14: 45720 | J14: 46101 | K14: 46101 | L14: =IF(_xlfn.XLOOKUP(D14, ABZ!A:A, ABZ!B:B, "", 0) = 0, "", _xlfn.XLOOKUP(D14, ABZ!A:A, ABZ!B:B, "", 0)) -> Channel Sales | M14: geliefert | N14: Hme | O14: BP-Technik | P14: D2C
A15: 4751_en-GB_smart_home_mit_fritz_und_matter_20260304-091540.xml | B15: 463 | D15: Pse | E15: EN | F15: Lisa | H15: LS-Tracker | I15: 45720 | J15: 46101 | K15: 46101 | L15: =IF(_xlfn.XLOOKUP(D15, ABZ!A:A, ABZ!B:B, "", 0) = 0, "", _xlfn.XLOOKUP(D15, ABZ!A:A, ABZ!B:B, "", 0)) -> Channel Sales | M15: geliefert | N15: Hme | O15: BP-Technik | P15: D2C
A16: 4752_en-GB_smart_home_mit_fritz_und_zigbee_20260304-091535.xml | B16: 1083 | D16: Pse | E16: EN | F16: Lisa | H16: LS-Tracker | I16: 45720 | J16: 46101 | K16: 46101 | L16: =IF(_xlfn.XLOOKUP(D16, ABZ!A:A, ABZ!B:B, "", 0) = 0, "", _xlfn.XLOOKUP(D16, ABZ!A:A, ABZ!B:B, "", 0)) -> Channel Sales | M16: geliefert | N16: Hme | O16: BP-Technik | P16: KM
A17: 4753_en-GB_schon_gewusst_20260304-091608.xml | B17: 166 | D17: Pse | E17: EN | F17: Lisa | H17: LS-Tracker | I17: 45720 | J17: 46101 | K17: 46101 | L17: =IF(_xlfn.XLOOKUP(D17, ABZ!A:A, ABZ!B:B, "", 0) = 0, "", _xlfn.XLOOKUP(D17, ABZ!A:A, ABZ!B:B, "", 0)) -> Channel Sales | M17: geliefert | N17: Hme | O17: BP-Technik | P17: KM
A18: 4754_en-GB_internetnutzung_im_unternehmen_gezielt_steuern_20260304-091522.xml | B18: 668 | D18: Pse | E18: EN | F18: Susan | H18: LS-Tracker | I18: 45720 | J18: 46101 | K18: 46101 | L18: =IF(_xlfn.XLOOKUP(D18, ABZ!A:A, ABZ!B:B, "", 0) = 0, "", _xlfn.XLOOKUP(D18, ABZ!A:A, ABZ!B:B, "", 0)) -> Channel Sales | M18: geliefert | N18: Hme | O18: BP-Technik | P18: KM
... A27: Übersetzung Stichpunkte für Social Media Karussell | B27: 53 | D27: KGo | E27: FR | F27: Marie | H27: Mail | I27: 46021 | J27: 46038 | K27: 46038 | L27: =IF(_xlfn.XLOOKUP(D27, ABZ!A:A, ABZ!B:B, "", 0) = 0, "", _xlfn.XLOOKUP(D27, ABZ!A:A, ABZ!B:B, "", 0)) -> D2C Ecommerce | M27: geliefert | N27: Hme | O27: Z:\Produkte\Texte Web, Marketing, etc\deutsch\2025.12 | P27: D2C
A28: 2026-01-06T14-01-35_PM-History-Texts.xml | D28: TJa | E28: DE | H28: Mail | I28: 46027 | J28: 46027 | K28: 46027 | L28: =IF(_xlfn.XLOOKUP(D28, ABZ!A:A, ABZ!B:B, "", 0) = 0, "", _xlfn.XLOOKUP(D28, ABZ!A:A, ABZ!B:B, "", 0)) -> Product Management | M28: geliefert | N28: FSc | O28: Z:\Produkte\F!Box allgemein\Info.txt\Release\25_Smart24-P2\2026.01 | P28: D2C
A29: 2026-01-06T14-40-23_PM-History-Texts_korr-de.xml | D29: TJa | E29: EN | F29: John | H29: Mail | I29: 46027 | J29: 46027 | K29: 46027 | L29: =IF(_xlfn.XLOOKUP(D29, ABZ!A:A, ABZ!B:B, "", 0) = 0, "", _xlfn.XLOOKUP(D29, ABZ!A:A, ABZ!B:B, "", 0)) -> Product Management | M29: geliefert | N29: FSc | O29: Z:\Produkte\F!Box allgemein\Info.txt\Release\25_Smart24-P2\2026.01 | P29: D2C
A30: IT-Standalone-NL-2026.docx | B30: 255 | D30: Jwg | E30: IT | F30: Cristina | G30: Laura | H30: Mail | I30: 46027 | J30: 46034 | K30: 46034 | L30: =IF(_xlfn.XLOOKUP(D30, ABZ!A:A, ABZ!B:B, "", 0) = 0, "", _xlfn.XLOOKUP(D30, ABZ!A:A, ABZ!B:B, "", 0)) -> Channel Sales | M30: geliefert | N30: Msi | O30: Z:\Produkte\FRITZ!com\deutsch\2026.01 | P30: D2C
A31: Übersetzung Januar newsletter NL.docx | B31: 269 | D31: Pse | E31: NL | F31: Angelique | H31: Mail | I31: 46027 | J31: 46031 | K31: 46035 | L31: =IF(_xlfn.XLOOKUP(D31, ABZ!A:A, ABZ!B:B, "", 0) = 0, "", _xlfn.XLOOKUP(D31, ABZ!A:A, ABZ!B:B, "", 0)) -> Channel Sales | N31: Msi | O31: Z:\Produkte\FRITZ!com\deutsch\2026.01 | P31: D2C
A32: v7 | B32: 519 | D32: Dhr | E32: EN | F32: John | H32: Mail | I32: 46027 | J32: 46028 | K32: 46028 | L32: =IF(_xlfn.XLOOKUP(D32, ABZ!A:A, ABZ!B:B, "", 0) = 0, "", _xlfn.XLOOKUP(D32, ABZ!A:A, ABZ!B:B, "", 0)) -> Corporate Communications | N32: Msi | O32: Z:\Produkte\FRITZ!com\deutsch\2026.01 | P32: Vertrieb
A33: Information zu Speicherkrise 18122025.docx | B33: 519 | D33: Dhr | E33: IT | F33: Cristina | G33: Laura | H33: Mail | I33: 46027 | J33: 46029 | K33: 46028 | L33: =IF(_xlfn.XLOOKUP(D33, ABZ!A:A, ABZ!B:B, "", 0) = 0, "", _xlfn.XLOOKUP(D33, ABZ!A:A, ABZ!B:B, "", 0)) -> Corporate Communications | N33: Msi | O33: Z:\Produkte\FRITZ!com\deutsch\2026.01 | P33: Entwicklung
A34: Information zu Speicherkrise 18122025.docx | B34: 519 | D34: Dhr | E34: NL | F34: Marion | G34: Angelique | H34: Mail | I34: 46027 | J34: 46029 | K34: 46028 | L34: =IF(_xlfn.XLOOKUP(D34, ABZ!A:A, ABZ!B:B, "", 0) = 0, "", _xlfn.XLOOKUP(D34, ABZ!A:A, ABZ!B:B, "", 0)) -> Corporate Communications | N34: Msi | O34: Z:\Produkte\FRITZ!com\deutsch\2026.01 | P34: Entwicklung
A35: METAFIELDS | D35: CST | E35: EN | F35: John | H35: Mail | I35: 46028 | J35: 46030 | K35: 46034 | L35: =IF(_xlfn.XLOOKUP(D35, ABZ!A:A, ABZ!B:B, "", 0) = 0, "", _xlfn.XLOOKUP(D35, ABZ!A:A, ABZ!B:B, "", 0)) -> D2C Ecommerce | N35: Lbo | O35: Z:\Produkte\FRITZ!com\deutsch\2026.01\KW2 | P35: Entwicklung
A36: METAFIELDS | D36: CST | E36: ES | F36: Helena | H36: Mail | I36: 46028 | J36: 46029 | K36: 46034 | L36: =IF(_xlfn.XLOOKUP(D36, ABZ!A:A, ABZ!B:B, "", 0) = 0, "", _xlfn.XLOOKUP(D36, ABZ!A:A, ABZ!B:B, "", 0)) -> D2C Ecommerce | M36: geliefert | N36: Lbo | O36: Z:\Produkte\FRITZ!com\deutsch\2026.01\KW2 | P36: Entwicklung
A37: METAFIELDS | D37: CST | E37: FR | F37: Martine | H37: Mail | I37: 46028 | J37: 46030 | K37: 46034 | L37: =IF(_xlfn.XLOOKUP(D37, ABZ!A:A, ABZ!B:B, "", 0) = 0, "", _xlfn.XLOOKUP(D37, ABZ!A:A, ABZ!B:B, "", 0)) -> D2C Ecommerce | M37: ausgecheckt | N37: Lbo | O37: Z:\Produkte\FRITZ!com\deutsch\2026.01\KW2 | P37: Entwicklung
A38: METAFIELDS | D38: CST | E38: IT | F38: Laura | H38: Mail | I38: 46028 | J38: 46030 | K38: 46034 | L38: =IF(_xlfn.XLOOKUP(D38, ABZ!A:A, ABZ!B:B, "", 0) = 0, "", _xlfn.XLOOKUP(D38, ABZ!A:A, ABZ!B:B, "", 0)) -> D2C Ecommerce | N38: Lbo | O38: Z:\Produkte\FRITZ!com\deutsch\2026.01\KW2 | P38: Entwicklung
A39: METAFIELDS | D39: CST | E39: NL | F39: Angelique | H39: Mail | I39: 46028 | J39: 46030 | K39: 46034 | L39: =IF(_xlfn.XLOOKUP(D39, ABZ!A:A, ABZ!B:B, "", 0) = 0, "", _xlfn.XLOOKUP(D39, ABZ!A:A, ABZ!B:B, "", 0)) -> D2C Ecommerce | M39: NICHT ausgecheckt | N39: Lbo | O39: Z:\Produkte\FRITZ!com\deutsch\2026.01\KW2 | P39: Entwicklung
A40: Newsletter-IT-01-26.docx | B40: 44 | D40: Jwg | E40: IT | F40: Cristina | G40: Laura | H40: Mail | I40: 46028 | J40: 46038 | K40: 46037 | L40: =IF(_xlfn.XLOOKUP(D40, ABZ!A:A, ABZ!B:B, "", 0) = 0, "", _xlfn.XLOOKUP(D40, ABZ!A:A, ABZ!B:B, "", 0)) -> Channel Sales | M40: geliefert | N40: Hme | O40: Z:\Produkte\FRITZ!com\deutsch\2026.01 | P40: Entwicklung
A41: Newsletter-ES-01-26.docx | B41: 128 | D41: Jwg | E41: ES | F41: Alba | H41: Mail | I41: 46028 | J41: 46038 | K41: 46037 | L41: =IF(_xlfn.XLOOKUP(D41, ABZ!A:A, ABZ!B:B, "", 0) = 0, "", _xlfn.XLOOKUP(D41, ABZ!A:A, ABZ!B:B, "", 0)) -> Channel Sales | M41: geliefert | N41: Hme | O41: Z:\Produkte\FRITZ!com\deutsch\2026.01 | P41: Kommunikation
A42: MyFapp_20260107-de.xml | D42: KSu | E42: DE | F42: Carsten | G42: Franziska | H42: jazz | I42: 46029 | J42: 46030 | K42: 46030 | L42: =IF(_xlfn.XLOOKUP(D42, ABZ!A:A, ABZ!B:B, "", 0) = 0, "", _xlfn.XLOOKUP(D42, ABZ!A:A, ABZ!B:B, "", 0)) -> User Interface & Clients | M42: geliefert | N42: FSc | O42: Z:\Produkte\F!Apps\FappMyF\GUI\Android\deutsch\2026.01 | P42: Vertrieb
A43: Übersetzung Newsletter Solden-de.docx | B43: 36 | D43: Atc | E43: Nl | F43: Angelique | H43: Mail | I43: 46029 | J43: 46034 | K43: 46031 | L43: =IF(_xlfn.XLOOKUP(D43, ABZ!A:A, ABZ!B:B, "", 0) = 0, "", _xlfn.XLOOKUP(D43, ABZ!A:A, ABZ!B:B, "", 0)) -> D2C Ecommerce | M43: geliefert | N43: Hme | O43: Z:\Produkte\FRITZ!com\deutsch\2026.01 | P43: D2C
A44: MyFapp_20260107-de.xml | D44: KSu | E44: EN | F44: John | H44: jazz | I44: 46029 | J44: 46034 | K44: 46034 | L44: =IF(_xlfn.XLOOKUP(D44, ABZ!A:A, ABZ!B:B, "", 0) = 0, "", _xlfn.XLOOKUP(D44, ABZ!A:A, ABZ!B:B, "", 0)) -> User Interface & Clients | M44: geliefert | N44: FSc | O44: Z:\Produkte\F!Apps\FappMyF\GUI\Android\deutsch\2026.01 | P44: D2C
A45: MyFapp_20260107-de.xml | D45: KSu | E45: Es | F45: Helena | H45: jazz | I45: 46029 | J45: 46034 | K45: 46034 | L45: =IF(_xlfn.XLOOKUP(D45, ABZ!A:A, ABZ!B:B, "", 0) = 0, "", _xlfn.XLOOKUP(D45, ABZ!A:A, ABZ!B:B, "", 0)) -> User Interface & Clients | M45: geliefert | N45: FSc | O45: Z:\Produkte\F!Apps\FappMyF\GUI\Android\deutsch\2026.01 | P45: D2C
A46: MyFapp_20260107-de.xml | D46: KSu | E46: Fr | F46: Marie | H46: jazz | I46: 46029 | J46: 46034 | K46: 46034 | L46: =IF(_xlfn.XLOOKUP(D46, ABZ!A:A, ABZ!B:B, "", 0) = 0, "", _xlfn.XLOOKUP(D46, ABZ!A:A, ABZ!B:B, "", 0)) -> User Interface & Clients | M46: geliefert | N46: FSc | O46: Z:\Produkte\F!Apps\FappMyF\GUI\Android\deutsch\2026.01 | P46: D2C
A47: MyFapp_20260107-de.xml | D47: KSu | E47: It | F47: Laura | H47: jazz | I47: 46029 | J47: 46034 | K47: 46034 | L47: =IF(_xlfn.XLOOKUP(D47, ABZ!A:A, ABZ!B:B, "", 0) = 0, "", _xlfn.XLOOKUP(D47, ABZ!A:A, ABZ!B:B, "", 0)) -> User Interface & Clients | M47: geliefert | N47: FSc | O47: Z:\Produkte\F!Apps\FappMyF\GUI\Android\deutsch\2026.01 | P47: D2C
A48: MyFapp_20260107-de.xml | D48: KSu | E48: Nl | F48: Angelique | H48: jazz | I48: 46029 | J48: 46034 | K48: 46034 | L48: =IF(_xlfn.XLOOKUP(D48, ABZ!A:A, ABZ!B:B, "", 0) = 0, "", _xlfn.XLOOKUP(D48, ABZ!A:A, ABZ!B:B, "", 0)) -> User Interface & Clients | M48: geliefert | N48: FSc | O48: Z:\Produkte\F!Apps\FappMyF\GUI\Android\deutsch\2026.01 | P48: KM
...

Sheet ABZ
A1: ADo | B1: User Interface & Clients | C1: Development & Production
A2: AGi | B2: Channel Sales | C2: Sales & Communication
A3: AJA | B3: D2C Ecommerce | C3: Sales & Communication
A4: AKh | B4: Corporate Communications | C4: Sales & Communication
A5: AKU | B5: Technical Communication | C5: Support
A6: ALb | B6: User Interface & Clients | C6: Development & Production
A7: ALe | B7: Vertriebscontrolling | C7: Finance & Corporates
A8: ALi | B8: Finance | C8: Finance & Corporates
A9: ALp | B9: Corporate Communications | C9: Sales & Communication
A10: APa | B10: Sales Marketing | C10: Sales & Communication
A11: ASr | B11: Provider Sales | C11: Sales & Communication
A12: ATc | B12: D2C Ecommerce | C12: Sales & Communication
... A134: YKo | B134: Human Resources | C134: Finance & Corporates

Sheet 2025
A1: Aufträge | B1: Vom | C1: Sprache | D1: Verantwortlich | E1: Jazz | F1: Ablageort | G1: Datum | H1: Lieferung | I1: Deadline | J1: Abteilung | K1: Status
A3: API-Reference-de.docx | B3: TKO | C3: EN | D3: Joe | E3: Mail | F3: Z:\Produkte\Texte Web, Marketing, etc\deutsch\2025.01 | G3: 45660 | H3: 45664 | I3: 45665 | J3: =IF(_xlfn.XLOOKUP(B3, ABZ!A:A, ABZ!B:B, "", 0) = 0, "", _xlfn.XLOOKUP(B3, ABZ!A:A, ABZ!B:B, "", 0)) -> Technical Communication
A4: access-link-delivery-repeater-template_de.properties | B4: MxG | C4: En | D4: Susan | E4: 137117 | F4: Z:\Produkte\MyFRITZ\deutsch\2024.12\MeshSetUebersetzung\Cloud-Mailing | G4: 45660 | H4: 45663 | I4: 45667 | J4: =IF(_xlfn.XLOOKUP(B4, ABZ!A:A, ABZ!B:B, "", 0) = 0, "", _xlfn.XLOOKUP(B4, ABZ!A:A, ABZ!B:B, "", 0)) -> IT
A5: access-link-delivery-repeater-template_de.properties | B5: MxG | C5: Es | D5: Helena | E5: 137117 | F5: Z:\Produkte\MyFRITZ\deutsch\2024.12\MeshSetUebersetzung\Cloud-Mailing | G5: 45660 | H5: 45670 | I5: 45667 | J5: =IF(_xlfn.XLOOKUP(B5, ABZ!A:A, ABZ!B:B, "", 0) = 0, "", _xlfn.XLOOKUP(B5, ABZ!A:A, ABZ!B:B, "", 0)) -> IT
A6: access-link-delivery-repeater-template_de.properties | B6: MxG | C6: Fr | D6: Marie/Martine | E6: 137117 | F6: Z:\Produkte\MyFRITZ\deutsch\2024.12\MeshSetUebersetzung\Cloud-Mailing | G6: 45660 | H6: 45664 | I6: 45667 | J6: =IF(_xlfn.XLOOKUP(B6, ABZ!A:A, ABZ!B:B, "", 0) = 0, "", _xlfn.XLOOKUP(B6, ABZ!A:A, ABZ!B:B, "", 0)) -> IT
A7: access-link-delivery-repeater-template_de.properties | B7: MxG | C7: It | D7: Laura | E7: 137117 | F7: Z:\Produkte\MyFRITZ\deutsch\2024.12\MeshSetUebersetzung\Cloud-Mailing | G7: 45660 | H7: 45300 | I7: 45667 | J7: =IF(_xlfn.XLOOKUP(B7, ABZ!A:A, ABZ!B:B, "", 0) = 0, "", _xlfn.XLOOKUP(B7, ABZ!A:A, ABZ!B:B, "", 0)) -> IT
A8: access-link-delivery-repeater-template_de.properties | B8: MxG | C8: Nl | D8: Angelique | E8: 137117 | F8: Z:\Produkte\MyFRITZ\deutsch\2024.12\MeshSetUebersetzung\Cloud-Mailing | G8: 45660 | H8: 45666 | I8: 45667 | J8: =IF(_xlfn.XLOOKUP(B8, ABZ!A:A, ABZ!B:B, "", 0) = 0, "", _xlfn.XLOOKUP(B8, ABZ!A:A, ABZ!B:B, "", 0)) -> IT
A9: botnet-detected-notification-repeater-template_de.properties | B9: MxG | C9: En | D9: Susan | E9: 137117 | F9: Z:\Produkte\MyFRITZ\deutsch\2024.12\MeshSetUebersetzung\Cloud-Mailing | G9: 45660 | H9: 45663 | I9: 45667 | J9: =IF(_xlfn.XLOOKUP(B9, ABZ!A:A, ABZ!B:B, "", 0) = 0, "", _xlfn.XLOOKUP(B9, ABZ!A:A, ABZ!B:B, "", 0)) -> IT
A10: botnet-detected-notification-repeater-template_de.properties | B10: MxG | C10: Es | D10: Helena | E10: 137117 | F10: Z:\Produkte\MyFRITZ\deutsch\2024.12\MeshSetUebersetzung\Cloud-Mailing | G10: 45660 | H10: 45670 | I10: 45667 | J10: =IF(_xlfn.XLOOKUP(B10, ABZ!A:A, ABZ!B:B, "", 0) = 0, "", _xlfn.XLOOKUP(B10, ABZ!A:A, ABZ!B:B, "", 0)) -> IT
A11: botnet-detected-notification-repeater-template_de.properties | B11: MxG | C11: Fr | D11: Marie/Martine | E11: 137117 | F11: Z:\Produkte\MyFRITZ\deutsch\2024.12\MeshSetUebersetzung\Cloud-Mailing | G11: 45660 | H11: 45664 | I11: 45667 | J11: =IF(_xlfn.XLOOKUP(B11, ABZ!A:A, ABZ!B:B, "", 0) = 0, "", _xlfn.XLOOKUP(B11, ABZ!A:A, ABZ!B:B, "", 0)) -> IT
A12: botnet-detected-notification-repeater-template_de.properties | B12: MxG | C12: It | D12: Laura | E12: 137117 | F12: Z:\Produkte\MyFRITZ\deutsch\2024.12\MeshSetUebersetzung\Cloud-Mailing | G12: 45660 | H12: 45300 | I12: 45667 | J12: =IF(_xlfn.XLOOKUP(B12, ABZ!A:A, ABZ!B:B, "", 0) = 0, "", _xlfn.XLOOKUP(B12, ABZ!A:A, ABZ!B:B, "", 0)) -> IT
A13: botnet-detected-notification-repeater-template_de.properties | B13: MxG | C13: Nl | D13: Angelique | E13: 137117 | F13: Z:\Produkte\MyFRITZ\deutsch\2024.12\MeshSetUebersetzung\Cloud-Mailing | G13: 45660 | H13: 45666 | I13: 45667 | J13: =IF(_xlfn.XLOOKUP(B13, ABZ!A:A, ABZ!B:B, "", 0) = 0, "", _xlfn.XLOOKUP(B13, ABZ!A:A, ABZ!B:B, "", 0)) -> IT
A14: confirm-box-repeater_de.properties | B14: MxG | C14: En | D14: Susan | E14: 137117 | F14: Z:\Produkte\MyFRITZ\deutsch\2024.12\MeshSetUebersetzung\Box-Management | G14: 45660 | H14: 45663 | I14: 45667 | J14: =IF(_xlfn.XLOOKUP(B14, ABZ!A:A, ABZ!B:B, "", 0) = 0, "", _xlfn.XLOOKUP(B14, ABZ!A:A, ABZ!B:B, "", 0)) -> IT
A15: confirm-box-repeater_de.properties | B15: MxG | C15: Es | D15: Helena | E15: 137117 | F15: Z:\Produkte\MyFRITZ\deutsch\2024.12\MeshSetUebersetzung\Box-Management | G15: 45660 | H15: 45670 | I15: 45667 | J15: =IF(_xlfn.XLOOKUP(B15, ABZ!A:A, ABZ!B:B, "", 0) = 0, "", _xlfn.XLOOKUP(B15, ABZ!A:A, ABZ!B:B, "", 0)) -> IT
... A83: update-succeeded-notification-repeater-template_de.properties | B83: MxG | C83: Nl | D83: Angelique | E83: 137117 | F83: Z:\Produkte\MyFRITZ\deutsch\2024.12\MeshSetUebersetzung\Cloud-Mailing | G83: 45660 | H83: 45666 | I83: 45667 | J83: =IF(_xlfn.XLOOKUP(B83, ABZ!A:A, ABZ!B:B, "", 0) = 0, "", _xlfn.XLOOKUP(B83, ABZ!A:A, ABZ!B:B, "", 0)) -> IT
A85: Gewinnerbenachrichtigung-Du-Form-de.docx | B85: Pse | C85: NL | D85: Angelique | F85: Z:\Produkte\Texte Web, Marketing, etc\deutsch\2025.01 | G85: 45665 | H85: 45667 | J85: =IF(_xlfn.XLOOKUP(B85, ABZ!A:A, ABZ!B:B, "", 0) = 0, "", _xlfn.XLOOKUP(B85, ABZ!A:A, ABZ!B:B, "", 0)) -> Channel Sales
A86: Gewinnerbenachrichtigung-Du-Form-de.docx | B86: Pse | C86: ES | D86: Marta/Helena | F86: Z:\Produkte\Texte Web, Marketing, etc\deutsch\2025.01 | G86: 45665 | H86: 45667 | J86: =IF(_xlfn.XLOOKUP(B86, ABZ!A:A, ABZ!B:B, "", 0) = 0, "", _xlfn.XLOOKUP(B86, ABZ!A:A, ABZ!B:B, "", 0)) -> Channel Sales
A87: Gewinnerbenachrichtigung-Du-Form-de.docx | B87: Pse | C87: IT | D87: Crisitna/Laura | F87: Z:\Produkte\Texte Web, Marketing, etc\deutsch\2025.01 | G87: 45665 | H87: 45301 | J87: =IF(_xlfn.XLOOKUP(B87, ABZ!A:A, ABZ!B:B, "", 0) = 0, "", _xlfn.XLOOKUP(B87, ABZ!A:A, ABZ!B:B, "", 0)) -> Channel Sales
A88: Newsletter ES Jan25.docx | B88: Jwg | C88: ES | D88: Marta/Helena | F88: Z:\Produkte\Texte Web, Marketing, etc\deutsch\2025.01 | G88: 45665 | H88: 45670 | I88: 45671 | J88: =IF(_xlfn.XLOOKUP(B88, ABZ!A:A, ABZ!B:B, "", 0) = 0, "", _xlfn.XLOOKUP(B88, ABZ!A:A, ABZ!B:B, "", 0)) -> Channel Sales
A89: FR_Amazon_Brand_Store_Texte_Übersetzungsbüro.docx | B89: apa | C89: FR | D89: Marie | F89: Z:\Produkte\Texte Web, Marketing, etc\deutsch\2025.01 | G89: 45666 | H89: 45674 | I89: 45672 | J89: =IF(_xlfn.XLOOKUP(B89, ABZ!A:A, ABZ!B:B, "", 0) = 0, "", _xlfn.XLOOKUP(B89, ABZ!A:A, ABZ!B:B, "", 0)) -> Sales Marketing
A90: 20241203_Provider International Pitch_1-16-de.pptx | B90: PWI | C90: EN | D90: Susan | F90: Z:\Produkte\Texte Web, Marketing, etc\deutsch\2025.01 | G90: 45667 | H90: 45670 | I90: 45671 | J90: =IF(_xlfn.XLOOKUP(B90, ABZ!A:A, ABZ!B:B, "", 0) = 0, "", _xlfn.XLOOKUP(B90, ABZ!A:A, ABZ!B:B, "", 0)) -> Sales Marketing
A91: Mesh Set 3000_[DE-Vorlage].idml | B91: Ost | C91: EN | D91: Susan | F91: Z:\Produkte\F!WLAN Repeater\Mesh Set 3000 (1200 AX)\international\2025.01\UeM | G91: 45667 | H91: 45670 | I91: 45672 | J91: =IF(_xlfn.XLOOKUP(B91, ABZ!A:A, ABZ!B:B, "", 0) = 0, "", _xlfn.XLOOKUP(B91, ABZ!A:A, ABZ!B:B, "", 0)) -> Technical Communication
A92: Mesh Set 3000_[DE-Vorlage].idml | B92: Ost | C92: FR | D92: Marie | F92: Z:\Produkte\F!WLAN Repeater\Mesh Set 3000 (1200 AX)\international\2025.01\UeM | G92: 45667 | H92: 45670 | I92: 45672 | J92: =IF(_xlfn.XLOOKUP(B92, ABZ!A:A, ABZ!B:B, "", 0) = 0, "", _xlfn.XLOOKUP(B92, ABZ!A:A, ABZ!B:B, "", 0)) -> Technical Communication
A93: Mesh Set 3000_[DE-Vorlage].idml | B93: Ost | C93: ES | D93: Helena | F93: Z:\Produkte\F!WLAN Repeater\Mesh Set 3000 (1200 AX)\international\2025.01\UeM | G93: 45667 | I93: 45672 | J93: =IF(_xlfn.XLOOKUP(B93, ABZ!A:A, ABZ!B:B, "", 0) = 0, "", _xlfn.XLOOKUP(B93, ABZ!A:A, ABZ!B:B, "", 0)) -> Technical Communication
A94: Mesh Set 3000_[DE-Vorlage].idml | B94: Ost | C94: IT | D94: Laura | F94: Z:\Produkte\F!WLAN Repeater\Mesh Set 3000 (1200 AX)\international\2025.01\UeM | G94: 45667 | H94: 45670 | I94: 45672 | J94: =IF(_xlfn.XLOOKUP(B94, ABZ!A:A, ABZ!B:B, "", 0) = 0, "", _xlfn.XLOOKUP(B94, ABZ!A:A, ABZ!B:B, "", 0)) -> Technical Communication
A95: Mesh Set 3000_[DE-Vorlage].idml | B95: Ost | C95: NL | D95: Angelique | F95: Z:\Produkte\F!WLAN Repeater\Mesh Set 3000 (1200 AX)\international\2025.01\UeM | G95: 45667 | H95: 45672 | I95: 45672 | J95: =IF(_xlfn.XLOOKUP(B95, ABZ!A:A, ABZ!B:B, "", 0) = 0, "", _xlfn.XLOOKUP(B95, ABZ!A:A, ABZ!B:B, "", 0)) -> Technical Communication
A96: Master_HB_Frep_MeshSet_V4-2025-01-10_D-00000082_T-00000762_EngineeringModules_de-DE_en-US.xml | B96: Cmi | C96: EN | D96: Susan | E96: Mail | F96: Z:\International\Tico\work\2025-01-10_D-00000082_T-00000762_de-DE_en-US.xml\untranslated | G96: 45667 | H96: 45670 | I96: 45684 | J96: =IF(_xlfn.XLOOKUP(B96, ABZ!A:A, ABZ!B:B, "", 0) = 0, "", _xlfn.XLOOKUP(B96, ABZ!A:A, ABZ!B:B, "", 0)) -> Technical Communication
A97: Master_HB_Frep_MeshSet_V4-2025-01-10_D-00000082_T-00000765_EngineeringModules_de-DE_it-IT.Fragments.xml | B97: Cmi | C97: IT | D97: Laura | E97: Mail | F97: Z:\International\Tico\work\2025-01-10_D-00000082_T-00000765_de-DE_it-IT.xml\untranslated | G97: 45667 | H97: 45686 | I97: 45684 | J97: =IF(_xlfn.XLOOKUP(B97, ABZ!A:A, ABZ!B:B, "", 0) = 0, "", _xlfn.XLOOKUP(B97, ABZ!A:A, ABZ!B:B, "", 0)) -> Technical Communication
A98: Master_HB_Frep_MeshSet_V4-2025-01-10_D-00000082_T-00000765_EngineeringModules_de-DE_it-IT.xml | B98: Cmi | C98: IT | D98: Laura | E98: Mail | F98: Z:\International\Tico\work\2025-01-10_D-00000082_T-00000765_de-DE_it-IT.xml\untranslated | G98: 45667 | H98: 45686 | I98: 45684 | J98: =IF(_xlfn.XLOOKUP(B98, ABZ!A:A, ABZ!B:B, "", 0) = 0, "", _xlfn.XLOOKUP(B98, ABZ!A:A, ABZ!B:B, "", 0)) -> Technical Communication
A99: Master_HB_Frep_MeshSet_V4-2025-01-10_D-00000082_T-00000764_EngineeringModules_de-DE_es-ES.xml | B99: Cmi | C99: ES | D99: Helena | E99: Mail | F99: Z:\International\Tico\work\2025-01-10_D-00000082_T-00000764_de-DE_es-ES.xml\untranslated | G99: 45667 | I99: 45684 | J99: =IF(_xlfn.XLOOKUP(B99, ABZ!A:A, ABZ!B:B, "", 0) = 0, "", _xlfn.XLOOKUP(B99, ABZ!A:A, ABZ!B:B, "", 0)) -> Technical Communication
A100: Master_HB_Frep_MeshSet_V4-2025-01-10_D-00000082_T-00000763_EngineeringModules_de-DE_fr-FR.xml | B100: Cmi | C100: FR | D100: Martine | E100: Mail | F100: Z:\International\Tico\work\2025-01-10_D-00000082_T-00000763_de-DE_fr-FR.xml\untranslated | G100: 45667 | H100: 45670 | I100: 45684 | J100: =IF(_xlfn.XLOOKUP(B100, ABZ!A:A, ABZ!B:B, "", 0) = 0, "", _xlfn.XLOOKUP(B100, ABZ!A:A, ABZ!B:B, "", 0)) -> Technical Communication
A101: Master_HB_Frep_MeshSet_V4-2025-01-10_D-00000082_T-00000766_EngineeringModules_de-DE_nl-NL.xml | B101: Cmi | C101: NL | D101: Angelique | E101: Mail | F101: Z:\International\Tico\work\2025-01-10_D-00000082_T-00000766_de-DE_nl-NL.xml\untranslated | G101: 45667 | H101: 45672 | I101: 45684 | J101: =IF(_xlfn.XLOOKUP(B101, ABZ!A:A, ABZ!B:B, "", 0) = 0, "", _xlfn.XLOOKUP(B101, ABZ!A:A, ABZ!B:B, "", 0)) -> Technical Communication
A102: Newsletter 01_2025-de-nl.docx | B102: PSe | C102: De | D102: Franziska | E102: Mail | F102: Z:\Produkte\Texte Web, Marketing, etc\deutsch\2025.01 | G102: 45670 | H102: 45670 | I102: 45670 | J102: =IF(_xlfn.XLOOKUP(B102, ABZ!A:A, ABZ!B:B, "", 0) = 0, "", _xlfn.XLOOKUP(B102, ABZ!A:A, ABZ!B:B, "", 0)) -> Channel Sales
A103: Newsletter 01_2025-de-nl.docx | B103: PSe | C103: Nl | D103: Angelique | E103: Mail | F103: Z:\Produkte\Texte Web, Marketing, etc\deutsch\2025.01 | G103: 45670 | H103: 45670 | I103: 45670 | J103: =IF(_xlfn.XLOOKUP(B103, ABZ!A:A, ABZ!B:B, "", 0) = 0, "", _xlfn.XLOOKUP(B103, ABZ!A:A, ABZ!B:B, "", 0)) -> Channel Sales
A104: Januar-Newsletter Österreich | B104: PSe | C104: De | D104: Franziska | E104: Mail | G104: 45670 | H104: 45670 | I104: 45670 | J104: =IF(_xlfn.XLOOKUP(B104, ABZ!A:A, ABZ!B:B, "", 0) = 0, "", _xlfn.XLOOKUP(B104, ABZ!A:A, ABZ!B:B, "", 0)) -> Channel Sales
A105: Januar-Newsletter Schweiz | B105: PSe | C105: De | D105: Franziska | E105: Mail | G105: 45670 | H105: 45670 | I105: 45670 | J105: =IF(_xlfn.XLOOKUP(B105, ABZ!A:A, ABZ!B:B, "", 0) = 0, "", _xlfn.XLOOKUP(B105, ABZ!A:A, ABZ!B:B, "", 0)) -> Channel Sales
A106: Kick-off_2025-de-en.docx | B106: AGi | C106: De | D106: Franziska | E106: Mail | F106: Z:\Produkte\Texte Web, Marketing, etc\deutsch\2025.01 | G106: 45671 | H106: 45671 | I106: 45671 | J106: =IF(_xlfn.XLOOKUP(B106, ABZ!A:A, ABZ!B:B, "", 0) = 0, "", _xlfn.XLOOKUP(B106, ABZ!A:A, ABZ!B:B, "", 0)) -> Channel Sales
A107: Kick-off_2025-de-en.docx | B107: AGi | C107: En | D107: Susan | E107: Mail | F107: Z:\Produkte\Texte Web, Marketing, etc\deutsch\2025.01 | G107: 45671 | H107: 45671 | I107: 45671 | J107: =IF(_xlfn.XLOOKUP(B107, ABZ!A:A, ABZ!B:B, "", 0) = 0, "", _xlfn.XLOOKUP(B107, ABZ!A:A, ABZ!B:B, "", 0)) -> Channel Sales
A108: Master_OLH_F!MeshSet_v3-2025-01-14_D-00000080_T-00000770_EngineeringModules_de-DE_it-IT.xml | B108: Cmi | C108: IT | D108: Laura | E108: Mail | F108: Z:\International\Tico\work\2025-01-14_D-00000080_T-00000770_de-DE_it-IT.xml\untranslated | G108: 45671 | H108: 45688 | I108: 45680 | J108: =IF(_xlfn.XLOOKUP(B108, ABZ!A:A, ABZ!B:B, "", 0) = 0, "", _xlfn.XLOOKUP(B108, ABZ!A:A, ABZ!B:B, "", 0)) -> Technical Communication
A109: Master_OLH_F!MeshSet_v3-2025-01-14_D-00000080_T-00000771_EngineeringModules_de-DE_nl-NL.xml | B109: Cmi | C109: NL | D109: Angelique | E109: Mail | F109: Z:\International\Tico\work\2025-01-14_D-00000080_T-00000771_de-DE_nl-NL.xml\untranslated | G109: 45671 | H109: 45680 | I109: 45680 | J109: =IF(_xlfn.XLOOKUP(B109, ABZ!A:A, ABZ!B:B, "", 0) = 0, "", _xlfn.XLOOKUP(B109, ABZ!A:A, ABZ!B:B, "", 0)) -> Technical Communication
...

Sheet 2024
A1: Aufträge | B1: Vom | C1: Sprache | D1: Korrektur | E1: Jazz | F1: Ablageort | G1: Datum | H1: Lieferung | I1: Deadline | J1: Abteilung | K1: Ist… | L1: Abteilung
A2: Newsletter-Dezember_de-ES.docx | B2: JWg | C2: ES | D2: Helena | E2: Mail | F2: Z:\Produkte\Texte Web, Marketing, etc\deutsch\2023.12 | G2: 45279 | H2: 45299 | I2: 45299 | J2: =_xlfn.XLOOKUP(B2, ABZ!A:A, ABZ!B:B, "", 0) -> Channel Sales | L2: {=_xlfn.XLOOKUP(B2:B3003, ABZ!A:A, ABZ!B:B, "", 0)} -> Channel Sales
A3: 7 Vorteile: FRITZ!Powerline 1240 AX mit Wi-Fi 6 und Gigabit über die Stromleitung | B3: JBy | C3: EN | D3: Joe | G3: 45301 | H3: 45322 | J3: =_xlfn.XLOOKUP(B3, ABZ!A:A, ABZ!B:B, "", 0)
A4: Produktseite: Mesh Set 4060 + 3000 AX Product Features | B4: JBy | C4: EN | D4: Joe | H4: 45322 | J4: =_xlfn.XLOOKUP(B4, ABZ!A:A, ABZ!B:B, "", 0)
A5: Produktseite: Mesh Set 4060 + 3000 AX Product Features | B5: JBy | C5: FR | D5: Martine | H5: 45322 | J5: =_xlfn.XLOOKUP(B5, ABZ!A:A, ABZ!B:B, "", 0)
A6: Produktseite: Mesh Set 4060 + 3000 AX Product Features | B6: JBy | C6: NL | D6: Marion/Angelique | H6: 45322 | J6: =_xlfn.XLOOKUP(B6, ABZ!A:A, ABZ!B:B, "", 0)
A7: Produktseite: Mesh Set 4060 + 3000 AX Product Features | B7: JBy | C7: ES | D7: Marta/Helena | H7: 45322 | J7: =_xlfn.XLOOKUP(B7, ABZ!A:A, ABZ!B:B, "", 0)
A8: Produktseite: Mesh Set 4060 + 3000 AX Product Features | B8: JBy | C8: IT | D8: Cristina/Laura | H8: 45322 | J8: =_xlfn.XLOOKUP(B8, ABZ!A:A, ABZ!B:B, "", 0)
A9: Produktseite: Mesh Set 4060 + 3000 AX Product Features | B9: JBy | C9: PL | D9: Yabylon | H9: 45322 | J9: =_xlfn.XLOOKUP(B9, ABZ!A:A, ABZ!B:B, "", 0)
A10: Produktseite: Mesh Set 7530 AX + 1200 Ed. Int. (20003051) | B10: JBy | C10: EN | D10: Joe | H10: 45322 | J10: =_xlfn.XLOOKUP(B10, ABZ!A:A, ABZ!B:B, "", 0)
A11: FRITZ!DECT 350 – Der Tür- und Fensterkontakt für smarte Möglichkeiten | B11: JBy | C11: EN | H11: 45322 | J11: =_xlfn.XLOOKUP(B11, ABZ!A:A, ABZ!B:B, "", 0)
A12: Sicheres Surfen im Internet | B12: JBy | C12: EN | H12: 45322 | J12: =_xlfn.XLOOKUP(B12, ABZ!A:A, ABZ!B:B, "", 0)
A13: Sicheres Surfen im Internet | B13: JBy | C13: FR | H13: 45322 | J13: =_xlfn.XLOOKUP(B13, ABZ!A:A, ABZ!B:B, "", 0)
A14: Sicheres Surfen im Internet | B14: JBy | C14: NL | H14: 45322 | J14: =_xlfn.XLOOKUP(B14, ABZ!A:A, ABZ!B:B, "", 0)
A15: Sicheres Surfen im Internet | B15: JBy | C15: ES | H15: 45322 | J15: =_xlfn.XLOOKUP(B15, ABZ!A:A, ABZ!B:B, "", 0)
A16: Sicheres Surfen im Internet | B16: JBy | C16: IT | H16: 45322 | J16: =_xlfn.XLOOKUP(B16, ABZ!A:A, ABZ!B:B, "", 0)
A17: Sicheres Surfen im Internet | B17: JBy | C17: PL | H17: 45322 | J17: =_xlfn.XLOOKUP(B17, ABZ!A:A, ABZ!B:B, "", 0)
A18: Alles über sichere Passwörter | B18: JBy | C18: EN | H18: 45322 | J18: =_xlfn.XLOOKUP(B18, ABZ!A:A, ABZ!B:B, "", 0)
A19: Alles über sichere Passwörter | B19: JBy | C19: FR | H19: 45322 | J19: =_xlfn.XLOOKUP(B19, ABZ!A:A, ABZ!B:B, "", 0)
A20: Alles über sichere Passwörter | B20: JBy | C20: NL | H20: 45322 | J20: =_xlfn.XLOOKUP(B20, ABZ!A:A, ABZ!B:B, "", 0)
A21: Alles über sichere Passwörter | B21: JBy | C21: ES | H21: 45322 | J21: =_xlfn.XLOOKUP(B21, ABZ!A:A, ABZ!B:B, "", 0)
A22: Alles über sichere Passwörter | B22: JBy | C22: IT | H22: 45322 | J22: =_xlfn.XLOOKUP(B22, ABZ!A:A, ABZ!B:B, "", 0)
... A78: Ändern oder lieber nicht? So erhöhen Sie die Sicherheit Ihrer Passwörter | B78: JBy | C78: NL | H78: 45322 | J78: =_xlfn.XLOOKUP(B78, ABZ!A:A, ABZ!B:B, "", 0)
A79: PI_AVM_RC_Glasfaser_Update_FRITZ!OS_7-80_1-de.docx | B79: CSa | C79: En | D79: Susan | E79: Mail | F79: Z:\Produkte\Texte Web, Marketing, etc\deutsch\2023.12 | G79: 45280 | H79: 45280 | I79: 45281 | J79: =_xlfn.XLOOKUP(B79, ABZ!A:A, ABZ!B:B, "", 0)
A80: Master_Move21_Version_30_2024-01-04_D-00000020_T-00000571_EngineeringModules_de-DE_es-ES.xml | B80: CMi | C80: ES | D80: Helena | F80: Z:\International\Tico\work\2024-01-04_D-00000020_T-00000571_de-DE_es-ES.xml | G80: 45295 | H80: 45299 | J80: =_xlfn.XLOOKUP(B80, ABZ!A:A, ABZ!B:B, "", 0) -> Technical Communication | L80: Technical Communication
A81: Master_Move21_Version_30_2024-01-04_D-00000020_T-00000570_EngineeringModules_de-DE_fr-FR.xml | B81: CMi | C81: FR | D81: Martine | F81: Z:\International\Tico\work\2024-01-04_D-00000020_T-00000570_de-DE_fr-FR.xml | G81: 45295 | H81: 45303 | J81: =_xlfn.XLOOKUP(B81, ABZ!A:A, ABZ!B:B, "", 0) -> Technical Communication | L81: Technical Communication
A82: Master_Move21_Version_30_2024-01-04_D-00000020_T-00000569_EngineeringModules_de-DE_en-US.xml | B82: CMi | C82: EN | D82: Susan | F82: Z:\International\Tico\work\2024-01-04_D-00000020_T-00000569_de-DE_en-US.xml | G82: 45295 | H82: 45299 | J82: =_xlfn.XLOOKUP(B82, ABZ!A:A, ABZ!B:B, "", 0) -> Technical Communication | L82: Technical Communication
A83: Master_Move21_Version_30_2024-01-04_D-00000020_T-00000572_EngineeringModules_de-DE_it-IT.xml | B83: CMi | C83: IT | D83: Laura | F83: Z:\International\Tico\work\2024-01-04_D-00000020_T-00000572_de-DE_it-IT.xml | G83: 45295 | H83: 45330 | J83: =_xlfn.XLOOKUP(B83, ABZ!A:A, ABZ!B:B, "", 0) -> Technical Communication | L83: Technical Communication
A84: Master_Move21_Version_30_2024-01-04_D-00000020_T-00000573_EngineeringModules_de-DE_nl-NL.xml | B84: CMi | C84: NL | D84: angelique | F84: Z:\International\Tico\work\2024-01-04_D-00000020_T-00000573_de-DE_nl-NL.xml | G84: 45295 | H84: 45303 | J84: =_xlfn.XLOOKUP(B84, ABZ!A:A, ABZ!B:B, "", 0) -> Technical Communication | L84: Technical Communication
A85: js3-i18n--2024-01-05.html | B85: SLm | C85: EN | D85: Susan | F85: \\file-fs-04.ads.avm.de\AVM\Anwendung\FileSplit | G85: 45299 | H85: 45299 | J85: =_xlfn.XLOOKUP(B85, ABZ!A:A, ABZ!B:B, "", 0) -> User Interface & Clients | L85: User Interface & Clients
A86: js3-i18n--2024-01-05.html | B86: SLm | C86: FR | D86: Martine | F86: \\file-fs-04.ads.avm.de\AVM\Anwendung\FileSplit | G86: 45299 | H86: 45299 | J86: =_xlfn.XLOOKUP(B86, ABZ!A:A, ABZ!B:B, "", 0) -> User Interface & Clients | L86: User Interface & Clients
A87: js3-i18n--2024-01-05.html | B87: SLm | C87: IT | D87: Laura | F87: \\file-fs-04.ads.avm.de\AVM\Anwendung\FileSplit | G87: 45299 | H87: 45299 | J87: =_xlfn.XLOOKUP(B87, ABZ!A:A, ABZ!B:B, "", 0) -> User Interface & Clients | L87: User Interface & Clients
A88: js3-i18n--2024-01-05.html | B88: SLm | C88: NL | D88: Angelique | F88: \\file-fs-04.ads.avm.de\AVM\Anwendung\FileSplit | G88: 45299 | H88: 45299 | J88: =_xlfn.XLOOKUP(B88, ABZ!A:A, ABZ!B:B, "", 0) -> User Interface & Clients | L88: User Interface & Clients
A89: js3-i18n--2024-01-05.html | B89: SLm | C89: ES | D89: Helena | F89: \\file-fs-04.ads.avm.de\AVM\Anwendung\FileSplit | G89: 45299 | H89: 45299 | J89: =_xlfn.XLOOKUP(B89, ABZ!A:A, ABZ!B:B, "", 0) -> User Interface & Clients | L89: User Interface & Clients
A90: js3-i18n--2024-01-05.html | B90: SLm | C90: PL | D90: Yabylon | F90: \\file-fs-04.ads.avm.de\AVM\Anwendung\FileSplit | G90: 45299 | H90: 45299 | J90: =_xlfn.XLOOKUP(B90, ABZ!A:A, ABZ!B:B, "", 0) -> User Interface & Clients | L90: User Interface & Clients
A91: 7690_Produktspezifikation_ 2023-11-de.docx | B91: AZi | C91: En | D91: Susan | E91: Mail | F91: Z:\Produkte\F!Box 7690\ExecSum\deutsch | G91: 45299 | H91: 45299 | I91: 45303 | J91: =_xlfn.XLOOKUP(B91, ABZ!A:A, ABZ!B:B, "", 0) -> Product Management | L91: Product Management
A92: Newsletter-IT-Jan.docx | B92: JWg | C92: IT | D92: Cristina/Laura | E92: Mail | F92: Z:\Produkte\Texte Web, Marketing, etc\italienisch\2024.01 | G92: 45301 | H92: 45302 | J92: =_xlfn.XLOOKUP(B92, ABZ!A:A, ABZ!B:B, "", 0) -> Channel Sales | L92: Channel Sales
A93: Business_Update_Januar-DE.docx | B93: SDa | C93: NL | D93: Angelique | E93: Mail | F93: Z:\Produkte\Texte Web, Marketing, etc\deutsch\2024.01 | G93: 45302 | H93: 45306 | I93: 45308 | J93: =_xlfn.XLOOKUP(B93, ABZ!A:A, ABZ!B:B, "", 0) -> Channel Sales | L93: Channel Sales
A94: Hintergrundstext zur Routerfreiheit (deutsch).docx | B94: JBy | C94: IT | D94: Cristina/Laura | E94: Mail | F94: Z:\Produkte\Texte Web, Marketing, etc\deutsch\2024.01 | G94: 45302 | H94: 45320 | J94: =_xlfn.XLOOKUP(B94, ABZ!A:A, ABZ!B:B, "", 0)
A95: Hintergrundstext zur Routerfreiheit (deutsch).docx | B95: JBy | C95: FR | D95: Martine | E95: Mail | F95: Z:\Produkte\Texte Web, Marketing, etc\deutsch\2024.01 | G95: 45302 | H95: 45310 | J95: =_xlfn.XLOOKUP(B95, ABZ!A:A, ABZ!B:B, "", 0)
...

Sheet 2023
A1: Aufträge | B1: Vom | C1: Sprache | D1: Korrektur | E1: Jazz | F1: Ablageort | G1: Datum | H1: Lieferung | I1: Deadline
A2: 0000_12.998.1.31_translate-from-de | B2: Abromeit | C2: EN | D2: Susan | F2: Z:\Produkte\F!Box allgemein\GUI\deutsch\2022.12 | G2: 44915 | H2: 44936 | I2: 44936
A3: 0000_12.998.1.31_translate-from-de | B3: Abromeit | C3: FR | D3: Martine | F3: Z:\Produkte\F!Box allgemein\GUI\deutsch\2022.12 | G3: 44915 | H3: 44936 | I3: 44936
A4: 0000_12.998.1.31_translate-from-de | B4: Abromeit | C4: IT | D4: Laura | F4: Z:\Produkte\F!Box allgemein\GUI\deutsch\2022.12 | G4: 44915 | H4: 44936 | I4: 44936
A5: 0000_12.998.1.31_translate-from-de | B5: Abromeit | C5: NL | D5: Angelique | F5: Z:\Produkte\F!Box allgemein\GUI\deutsch\2022.12 | G5: 44915 | H5: 44936 | I5: 44936
A6: 0000_12.998.1.31_translate-from-de | B6: Abromeit | C6: ES | D6: Helena | F6: Z:\Produkte\F!Box allgemein\GUI\deutsch\2022.12 | G6: 44915 | H6: 44936 | I6: 44936
A7: 0000_12.998.1.31_translate-from-de-to-pl | B7: Abromeit | C7: PL | D7: Yabylon | F7: Z:\Produkte\F!Box allgemein\GUI\deutsch\2022.12 | G7: 44915 | H7: 44936 | I7: 44936
A8: AVM-Erlebniswelt-de | B8: Luisa | C8: NL | D8: Angelique | G8: 44916 | H8: 44936 | I8: 44936
A9: FappFon_20221222_strings-de | B9: Andre Dossmann | C9: EN | D9: Susan | E9: Entwicklungsauftrag 110394 | F9: Z:\Produkte\F!Apps\FappFon\GUI\Android\deutsch\2022.12 | G9: 44917 | H9: 44936 | I9: 44936
A10: FappFon_20221222_strings-de | C10: IT | D10: Laura | E10: Entwicklungsauftrag 110394 | F10: Z:\Produkte\F!Apps\FappFon\GUI\Android\deutsch\2022.12 | G10: 44917 | H10: 44936 | I10: 44936
A11: Master_Version_13_2023-01-10_D-00000020_T-00000432_EngineeringModules_de-DE_es-ES | B11: doku | C11: ES | D11: Helena | F11: Z:\International\Tico\work\2023-01-10_D-00000020_T-00000432_de-DE_es-ES.xml | G11: 44936 | H11: 44941 | I11: 44941
A12: Master_Version_13_2023-01-10_D-00000020_T-00000434_EngineeringModules_de-DE_nl-NL | B12: doku | C12: NL | D12: Angelique | F12: Z:\International\Tico\work\2023-01-10_D-00000020_T-00000434_de-DE_nl-NL.xml | G12: 44936 | H12: 44945 | I12: 44945
A13: Master_Version_13_2023-01-10_D-00000020_T-00000430_EngineeringModules_de-DE_en-US | B13: doku | C13: US | D13: Susan | F13: Z:\International\Tico\work\2023-01-10_D-00000020_T-00000430_de-DE_en-US.xml | G13: 44936 | H13: 44941 | I13: 44941
A14: Master_Version_13_2023-01-10_D-00000020_T-00000431_EngineeringModules_de-DE_fr-FR | B14: doku | C14: FR | D14: Martine | F14: Z:\International\Tico\work\2023-01-10_D-00000020_T-00000431_de-DE_fr-FR.xml | G14: 44936 | H14: 44941 | I14: 44941
A15: Uebersetzung_BU_Januar_DE-NL | B15: Luisa | C15: NL | D15: Angelique | F15: Z:\Produkte\Texte Web, Marketing, etc\deutsch\2023.01 | G15: 44937 | H15: 44942 | I15: 44942
A16: Produkte hinter login ES_IT_NL | B16: Luisa | C16: ES | D16: Helena | F16: Z:\Produkte\Texte Web, Marketing, etc\deutsch\2023.01 | G16: 44938 | H16: 44946 | I16: 44946
A17: Produkte hinter login ES_IT_NL | B17: Luisa | C17: IT | D17: Laura | F17: Z:\Produkte\Texte Web, Marketing, etc\deutsch\2023.01 | G17: 44938 | H17: 44946 | I17: 44946
A18: Produkte hinter login ES_IT_NL | B18: Luisa | C18: NL | D18: Angelique | F18: Z:\Produkte\Texte Web, Marketing, etc\deutsch\2023.01 | G18: 44938 | H18: 44946 | I18: 44946
A19: Übersetzung Abmeldung CleverReach IT, ES, NL | B19: Luisa | C19: ES | D19: Helena | F19: Z:\Produkte\Texte Web, Marketing, etc\deutsch\2023.01 | G19: 44942 | H19: 44956 | I19: 44956
A20: Übersetzung Abmeldung CleverReach IT, ES, NL | B20: Luisa | C20: IT | D20: Cristina | F20: Z:\Produkte\Texte Web, Marketing, etc\deutsch\2023.01 | G20: 44942 | H20: 44956 | I20: 44956
A21: Übersetzung Abmeldung CleverReach IT, ES, NL | B21: Luisa | C21: NL | D21: Angelique | F21: Z:\Produkte\Texte Web, Marketing, etc\deutsch\2023.01 | G21: 44942 | H21: 44956 | I21: 44956
A22: Übersetzung_DE-NL_IT_ES | B22: Johannes Wiggert | C22: ES | D22: Helena | F22: Z:\Produkte\Texte Web, Marketing, etc\deutsch\2023.01 | G22: 44943 | H22: 44946 | I22: 44946
... A51: translate-from-de-to-pl | B51: Abromeit | C51: PL | D51: Yabylon | F51: Z:\Produkte\F!Box allgemein\GUI\deutsch\2023.02 | G51: 44960 | H51: 44964 | I51: 44964
A52: FappFon_20230201_de-US.xliff | B52: K. Nuding | C52: En | D52: Lisa | E52: Aufgabe 112871 | F52: Z:\Produkte\F!Apps\FappFon\GUI\iOS\englisch\2023.02 | G52: 44966 | H52: 44969 | I52: 44969
A53: FappFon_20230201_de-IT.xliff | B53: K. Nuding | C53: It | D53: Laua | E53: Aufgabe 112871 | F53: Z:\Produkte\F!Apps\FappFon\GUI\iOS\italienisch\2023.02 | G53: 44966 | H53: 44969 | I53: 44969
A54: Broschüre_Projekte mit AVM_gekürzt-de | B54: Christian Oloeslagers | C54: NL | D54: Angelique | F54: Z:\Produkte\Texte Web, Marketing, etc\deutsch\2023.02 | G54: 44966 | H54: 44980 | I54: 44980
A55: Broschüre_Projekte mit AVM_Takko-de | B55: Christian Oloeslagers | C55: NL | D55: Angelique | F55: Z:\Produkte\Texte Web, Marketing, etc\deutsch\2023.02 | G55: 44966 | H55: 44980 | I55: 44980
A56: Master Hilfe Datenschutzerklärung
A57: Master Hilfe Datenschutzerklärung Apps
A58: Changelogs.docx | B58: Felix Hörger, S. Marek | C58: En | D58: Lisa | E58: Aufgabe 110751 | F58: Z:\Produkte\F!Apps\Apps_allgemein | G58: 44971 | H58: 44972 | I58: 44972
A59: Changelogs.docx | B59: Felix Hörger, S. Marek | C59: It | D59: Laura | E59: Aufgabe 110751 | F59: Z:\Produkte\F!Apps\Apps_allgemein | G59: 44971 | H59: 44972 | I59: 44972
A60: FappBoxSetup_20230214_de-US.xliff | B60: K. Krug, S. Marek | D60: Lisa | E60: Story 82740 | F60: Z:\Produkte\F!Apps\FappBoxSetup\englisch\2023.02 | G60: 44974 | H60: 44977 | I60: 44977
A61: FappBoxSetup_20230214_de-IT.xliff | B61: K. Krug, S. Marek | D61: Laura | E61: Story 82740 | F61: Z:\Produkte\F!Apps\FappBoxSetup\italienisch\2023.02 | G61: 44974 | H61: 44977 | I61: 44977
A62: 0000_12-998-1-37_translate-from-de.xml | B62: Abromeit | C62: EN | D62: Susan | F62: Z:\Produkte\F!Box allgemein\GUI\deutsch\2023.02 | G62: 44977 | H62: 44979 | I62: 44979
A63: 0000_12-998-1-37_translate-from-de.xml | B63: Abromeit | C63: IT | D63: Laura | F63: Z:\Produkte\F!Box allgemein\GUI\deutsch\2023.02 | G63: 44977 | H63: 44979 | I63: 44979
A64: 0000_12-998-1-37_translate-from-de.xml | B64: Abromeit | C64: FR | D64: Martine | F64: Z:\Produkte\F!Box allgemein\GUI\deutsch\2023.02 | G64: 44977 | H64: 44979 | I64: 44979
A65: 0000_12-998-1-37_translate-from-de.xml | B65: Abromeit | C65: NL | D65: Angelique | F65: Z:\Produkte\F!Box allgemein\GUI\deutsch\2023.02 | G65: 44977 | H65: 44979 | I65: 44979
A66: 0000_12-998-1-37_translate-from-de.xml | B66: Abromeit | C66: ES | D66: Helena | F66: Z:\Produkte\F!Box allgemein\GUI\deutsch\2023.02 | G66: 44977 | H66: 44979 | I66: 44979
A67: 0000_12-998-1-37_translate-from-de-to-pl.xml | B67: Abromeit | C67: PL | D67: Yabylon | F67: Z:\Produkte\F!Box allgemein\GUI\polnisch\2023.02 | G67: 44977 | H67: 44979 | I67: 44979
A68: infoLab-de.docx | B68: Sylvia Stammberger | C68: En | D68: Susan | F68: Z:\Produkte\F!Box allgemein\Info.txt\22_Move21\2023.02 | G68: 44977 | H68: 44978 | I68: 44978
...

Sheet 2022
A1: 2024 | B1: Vom | C1: Sprache | D1: Korrektur | E1: Jazz | F1: Ablageort | G1: Datum | H1: Lieferung | I1: Deadline
A2: GUI Datei | B2: Gunther Abromeit | C2: alle | G2: 44782 | H2: 44802 | I2: 44802
A3: FappWLAN_20220811_strings-de | B3: Sebastian Marek | C3: DE | D3: Eva | G3: 44789 | H3: 44790 | I3: 44790
A4: FAppMyFRITZ_20220816-de | B4: Axel Zehnden | C4: DE | D4: Linda | E4: Aufgabe 107362 | G4: 44789 | H4: 44790 | I4: 44790
A5: FAppMyFRITZ_20220816-en | B5: Axel Zehnden | C5: EN | D5: Susan | E5: Aufgabe 107362 | G5: 44790 | H5: 44795 | I5: 44795
A6: FAppMyFRITZ_20220816-it | B6: Axel Zehnden | C6: IT | E6: Aufgabe 107362 | G6: 44790 | H6: 44796 | I6: 44796
A7: FappSmartHome_20220816-de | B7: Karsten Krug | C7: DE | D7: Linda | E7: Aufgabe 107266 | G7: 44789 | H7: 44789 | I7: 44789
A8: FRITZ!App Smart Home 1.8.7 | B8: Nico Riemer | E8: Story 107472 | G8: 44785 | H8: 44788 | I8: 44788
A9: FRITZ!App Smart Home Android | B9: Nico Riemer | E9: Story 107489 | G9: 44791 | H9: 44795 | I9: 44795
A10: Online Hilfe Master Box | C10: FR | D10: martine | G10: 44791 | H10: 44796 | I10: 44796
A11: Online Hilfe Master Box | C11: EN | D11: Susan | G11: 44791 | H11: 44796 | I11: 44796
A12: Handbuch 3000 AX Korrektur | B12: Linh | C12: FR | D12: Marie | G12: 44795 | H12: 44810 | I12: 44810
A13: Handbuch 3000 AX Korrektur | B13: Linh | C13: EN | D13: Lisa | G13: 44795
A14: Handbuch 3000 AX Korrektur | B14: Linh | C14: IT | D14: Laura? | G14: 44795
A15: Handbuch 3000 AX Korrektur | B15: Linh | C15: ES | D15: Helena | G15: 44795
A16: Handbuch 3000 AX Korrektur | B16: Linh | C16: FR | D16: Marie | G16: 44795 | H16: 44797 | I16: 44797
A17: FappSmartHome_20220822-en | B17: Karsten Krug | C17: EN | D17: Susan | E17: Aufgabe 107266 | G17: 44795 | H17: 44796 | I17: 44796
A18: FappSmartHome_20220822-it | B18: Karsten Krug | C18: IT | D18: Laura | E18: Aufgabe 107266 | G18: 44795 | H18: 44796 | I18: 44796
A19: Lektorat Händler-Newsflash DE | B19: Alice Gimmler | C19: DE | D19: Linda | G19: 44795 | H19: 44796 | I19: 44796
A20: Online Hilfe Master Powerline Version 3 | B20: DOKU | C20: EN | D20: Susan | G20: 44796 | H20: 44796 | I20: 44796
A21: Online Hilfe Master Powerline Version 3 | B21: DOKU | C21: FR | D21: Martine | G21: 44796 | H21: 44797 | I21: 44797
A22: 20220820_LP_Router_Rep_Stick-de | B22: Angelika Paulus | C22: FR | D22: Martine | G22: 44796 | H22: 44802 | I22: 44802
A23: 20220820_LP_Router_Rep_Stick-de | B23: Angelika Paulus | C23: IT | D23: Laura | G23: 44796 | H23: 44803 | I23: 44803
A24: Korrektur Repeater 120AX slo | B24: Mehran Reuter | C24: SLO | D24: Helena | G24: 44796
A25: Übersetzung Booklet DECT 100 int | B25: Daniel | C25: DE | G25: 44796 | H25: 44812 | I25: 44812
A26: Übersetzung Booklet DECT 100 int | C26: EN | D26: Susan | G26: 44796 | H26: 44812 | I26: 44812
A27: Übersetzung Booklet DECT 100 int | C27: IT | D27: Laura | G27: 44796 | H27: 44812 | I27: 44812
A28: Übersetzung Booklet DECT 100 int | C28: FR | D28: Martine | G28: 44796 | H28: 44812 | I28: 44812
A29: Übersetzung Booklet DECT 100 int | C29: ES | D29: Helena | G29: 44796 | H29: 44812 | I29: 44812
A30: Übersetzung Booklet DECT 100 int | C30: NL | D30: Angelique | G30: 44809 | H30: 44811 | I30: 44811
A31: Master_Version_4_2022-08-01_D-00000051_T-00000365_EngineeringModules_de-DE_fr-FR | B31: DOKU | C31: FR | D31: Martine | G31: 44774 | H31: 44797 | I31: 44797
A32: Neuer Übersetzungsauftrag AVM - Onepager - IFA 2022 - EN | B32: Prese | C32: EN | D32: Lisa | G32: 44796 | H32: 44798 | I32: 44798
A33: Neuer Übersetzungsauftrag AVM - Onepager - IFA 2022 - EN | C33: IT | D33: Laura | G33: 44796 | H33: 44799 | I33: 44799
A34: Flexibel mit Mobilfunk-de | B34: Johannes Wiggert | C34: IT | D34: Cristina | G34: 44797 | H34: 44817 | I34: 44817
A35: Flexibel mit Mobilfunk-de | B35: Johannes Wiggert | C35: ES | D35: Helena | G35: 44797 | H35: 44817 | I35: 44817
A36: Flexibel mit Mobilfunk-de | B36: Johannes Wiggert | C36: NL | D36: Angelique | G36: 44797 | H36: 44812 | I36: 44812
A37: AlpArray blickt tief in die Erde-de | B37: Johannes Wiggert | D37: Cristina | H37: 44812 | I37: 44812
A38: AlpArray blickt tief in die Erde-de | B38: Johannes Wiggert | C38: ES | D38: Helena | G38: 44797 | H38: 44812 | I38: 44812
A39: AlpArray blickt tief in die Erde-de | B39: Johannes Wiggert | C39: NL | D39: Angelique | G39: 44797 | H39: 44812 | I39: 44812
A40: iOS Smart Home: Changelog Version 1.6.4 | B40: Michael Rommel | C40: DE | D40: Linda | E40: Aufgabe 105834 | G40: 44797 | H40: 44798 | I40: 44798
...
