Workbook

Sheet Tabelle1
A3: Zeilenbeschriftungen | B3: Summe von EN | C3: Summe von IT | D3: Summe von NL | E3: Summe von PL | F3: Summe von SL | G3: Summe von SV | H3: Summe von FI | I3: Summe von NW | J3: Summe von DA
A4: CorporateLegal | E4: 101.97
A5: D2C | C5: 1905.8 | D5: 235.14 | E5: 1139.98 | F5: 159.96 | H5: 159.54 | I5: 159.96 | J5: 152.8
A6: ENT | E6: 4390.99 | F6: 4323.73
A7: Finance | B7: 104.58 | E7: 680.82
A8: SUP | C8: 30.36 | E8: 1227.62 | F8: 140.23 | G8: 2213.06 | H8: 2510.58 | I8: 2635.25 | J8: 2421.94
A9: VTR | C9: 3281.38 | D9: 320.73 | E9: 621.51
A10: Gesamtergebnis | B10: 104.58 | C10: 5217.54 | D10: 555.87 | E10: 8162.89 | F10: 4623.92 | G10: 2213.06 | H10: 2670.12 | I10: 2795.21 | J10: 2574.74

Sheet Dashboard
A1: TCO- Kosten pro Sprache 2026
A3: Sprache | B3: Kosten | E3: Bereich | F3: DA | G3: EN | H3: ES | I3: GR | J3: FI | K3: IT | L3: NL | M3: NW | N3: PL | O3: PT | P3: SL | Q3: SV
A4: CZ | B4: =SUM(INDEX('2026'!$E$2:$Q$938,,MATCH(A4,'2026'!$E$1:$Q$1,0))) -> 0 | E4: CorporateLegal | F4: =SUMIFS('2026'!P:P,'2026'!C:C,Dashboard!E4) -> 0 | G4: =SUMIFS('2026'!E:E,'2026'!C:C,Dashboard!E4) -> 104.58 | H4: =SUMIFS('2026'!G:G,'2026'!C:C,Dashboard!E4) -> 91.21 | I4: =SUMIFS('2026'!Q:Q,'2026'!C:C,Dashboard!E5) -> 0 | J4: =SUMIFS('2026'!N:N,'2026'!C:C,Dashboard!E4) -> 0 | K4: =SUMIFS('2026'!F:F,'2026'!C:C,Dashboard!E4) -> 0 | L4: =SUMIFS('2026'!H:H,'2026'!C:C,Dashboard!E4) -> 0 | M4: =SUMIFS('2026'!O:O,'2026'!C:C,Dashboard!E4) -> 0 | N4: =SUMIFS('2026'!I:I,'2026'!C:C,Dashboard!E4) -> 782.79 | O4: =SUMIFS('2026'!J:J,'2026'!C:C,Dashboard!E4) -> 0 | P4: =SUMIFS('2026'!L:L,'2026'!C:C,Dashboard!E4) -> 0 | Q4: =SUMIFS('2026'!M:M,'2026'!C:C,Dashboard!E4) -> 0
A5: DA | B5: =SUM(INDEX('2026'!$E$2:$Q$938,,MATCH(A5,'2026'!$E$1:$Q$1,0))) -> 2899.31 | E5: D2C Ecommerce | F5: =SUMIFS('2026'!P:P,'2026'!C:C,Dashboard!E5) -> 152.8 | G5: =SUMIFS('2026'!E:E,'2026'!C:C,Dashboard!E5) -> 0 | H5: =SUMIFS('2026'!P:P,'2026'!G:G,Dashboard!E5) -> 0 | I5: =SUMIFS('2026'!Q:Q,'2026'!C:C,Dashboard!E6) -> 347.83 | J5: =SUMIFS('2026'!N:N,'2026'!C:C,Dashboard!E5) -> 159.54 | K5: =SUMIFS('2026'!F:F,'2026'!C:C,Dashboard!E5) -> 5598.06 | L5: =SUMIFS('2026'!H:H,'2026'!C:C,Dashboard!E5) -> 235.14 | M5: =SUMIFS('2026'!O:O,'2026'!C:C,Dashboard!E5) -> 159.96 | N5: =SUMIFS('2026'!I:I,'2026'!C:C,Dashboard!E5) -> 1209 | O5: =SUMIFS('2026'!J:J,'2026'!C:C,Dashboard!E5) -> 0 | P5: =SUMIFS('2026'!L:L,'2026'!C:C,Dashboard!E5) -> 159.96 | Q5: =SUMIFS('2026'!M:M,'2026'!C:C,Dashboard!E5) -> 0
A6: EN | B6: =SUM(INDEX('2026'!$E$2:$Q$938,,MATCH(A6,'2026'!$E$1:$Q$1,0))) -> 104.58 | E6: User Interface & Clients | F6: =SUMIFS('2026'!P:P,'2026'!C:C,Dashboard!E6) -> 0 | G6: =SUMIFS('2026'!E:E,'2026'!C:C,Dashboard!E6) -> 0 | H6: =SUMIFS('2026'!R:R,'2026'!G:G,Dashboard!G6) -> 0 | I6: =SUMIFS('2026'!Q:Q,'2026'!C:C,Dashboard!E7) -> 0 | J6: =SUMIFS('2026'!N:N,'2026'!C:C,Dashboard!E6) -> 0 | K6: =SUMIFS('2026'!F:F,'2026'!C:C,Dashboard!E6) -> 19.65 | L6: =SUMIFS('2026'!H:H,'2026'!C:C,Dashboard!E6) -> 0 | M6: =SUMIFS('2026'!O:O,'2026'!C:C,Dashboard!E6) -> 0 | N6: =SUMIFS('2026'!I:I,'2026'!C:C,Dashboard!E6) -> 8166.23 | O6: =SUMIFS('2026'!J:J,'2026'!C:C,Dashboard!E6) -> 0 | P6: =SUMIFS('2026'!L:L,'2026'!C:C,Dashboard!E6) -> 10929.84 | Q6: =SUMIFS('2026'!M:M,'2026'!C:C,Dashboard!E6) -> 0
A7: ES | B7: =SUM(INDEX('2026'!$E$2:$Q$938,,MATCH(A7,'2026'!$E$1:$Q$1,0))) -> 91.21 | E7: Support | F7: =SUMIFS('2026'!P:P,'2026'!C:C,Dashboard!E7) -> 0 | G7: =SUMIFS('2026'!E:E,'2026'!C:C,Dashboard!E7) -> 0 | H7: =SUMIFS('2026'!R:R,'2026'!G:G,Dashboard!G7) -> 0 | I7: =SUMIFS('2026'!Q:Q,'2026'!C:C,Dashboard!E8) -> 223.43 | J7: =SUMIFS('2026'!N:N,'2026'!C:C,Dashboard!E7) -> 0 | K7: =SUMIFS('2026'!F:F,'2026'!C:C,Dashboard!E7) -> 0 | L7: =SUMIFS('2026'!H:H,'2026'!C:C,Dashboard!E7) -> 0 | M7: =SUMIFS('2026'!O:O,'2026'!C:C,Dashboard!E7) -> 0 | N7: =SUMIFS('2026'!I:I,'2026'!C:C,Dashboard!E7) -> 668.85 | O7: =SUMIFS('2026'!J:J,'2026'!C:C,Dashboard!E7) -> 0 | P7: =SUMIFS('2026'!L:L,'2026'!C:C,Dashboard!E7) -> 69.02 | Q7: =SUMIFS('2026'!M:M,'2026'!C:C,Dashboard!E7) -> 0
A8: GR | B8: =SUM(INDEX('2026'!$E$2:$Q$938,,MATCH(A8,'2026'!$E$1:$Q$1,0))) -> 1178.21 | E8: Sales Marketing | F8: =SUMIFS('2026'!P:P,'2026'!C:C,Dashboard!E8) -> 0 | G8: =SUMIFS('2026'!E:E,'2026'!C:C,Dashboard!E8) -> 0 | H8: =SUMIFS('2026'!R:R,'2026'!G:G,Dashboard!G8) -> 0 | I8: =SUMIFS('2026'!Q:Q,'2026'!C:C,Dashboard!E9) -> 564.82 | J8: =SUMIFS('2026'!N:N,'2026'!C:C,Dashboard!E8) -> 0 | K8: =SUMIFS('2026'!F:F,'2026'!C:C,Dashboard!E8) -> 0 | L8: =SUMIFS('2026'!H:H,'2026'!C:C,Dashboard!E8) -> 0 | M8: =SUMIFS('2026'!O:O,'2026'!C:C,Dashboard!E8) -> 0 | N8: =SUMIFS('2026'!I:I,'2026'!C:C,Dashboard!E8) -> 491.33 | O8: =SUMIFS('2026'!J:J,'2026'!C:C,Dashboard!E8) -> 0 | P8: =SUMIFS('2026'!L:L,'2026'!C:C,Dashboard!E8) -> 0 | Q8: =SUMIFS('2026'!M:M,'2026'!C:C,Dashboard!E8) -> 0
A9: FI | B9: =SUM(INDEX('2026'!$E$2:$Q$938,,MATCH(A9,'2026'!$E$1:$Q$1,0))) -> 2937.73 | E9: Channel Sales | F9: =SUMIFS('2026'!P:P,'2026'!C:C,Dashboard!E9) -> 0 | G9: =SUMIFS('2026'!E:E,'2026'!C:C,Dashboard!E9) -> 0 | H9: =SUMIFS('2026'!R:R,'2026'!G:G,Dashboard!G9) -> 0 | I9: =SUMIFS('2026'!Q:Q,'2026'!C:C,Dashboard!E10) -> 42.13 | J9: =SUMIFS('2026'!N:N,'2026'!C:C,Dashboard!E9) -> 0 | K9: =SUMIFS('2026'!F:F,'2026'!C:C,Dashboard!E9) -> 4802.71 | L9: =SUMIFS('2026'!H:H,'2026'!C:C,Dashboard!E9) -> 1910.91 | M9: =SUMIFS('2026'!O:O,'2026'!C:C,Dashboard!E9) -> 0 | N9: =SUMIFS('2026'!I:I,'2026'!C:C,Dashboard!E9) -> 69.02 | O9: =SUMIFS('2026'!J:J,'2026'!C:C,Dashboard!E9) -> 0 | P9: =SUMIFS('2026'!L:L,'2026'!C:C,Dashboard!E9) -> 0 | Q9: =SUMIFS('2026'!M:M,'2026'!C:C,Dashboard!E9) -> 0
A10: IT | B10: =SUM(INDEX('2026'!$E$2:$Q$938,,MATCH(A10,'2026'!$E$1:$Q$1,0))) -> 10450.78 | E10: Technical Communication | F10: =SUMIFS('2026'!P:P,'2026'!C:C,Dashboard!E10) -> 2746.51 | G10: =SUMIFS('2026'!E:E,'2026'!C:C,Dashboard!E10) -> 0 | H10: =SUMIFS('2026'!R:R,'2026'!G:G,Dashboard!G10) -> 0 | I10: =SUMIFS('2026'!Q:Q,'2026'!C:C,Dashboard!E11) -> 0 | J10: =SUMIFS('2026'!N:N,'2026'!C:C,Dashboard!E10) -> 2778.19 | K10: =SUMIFS('2026'!F:F,'2026'!C:C,Dashboard!E10) -> 30.36 | L10: =SUMIFS('2026'!H:H,'2026'!C:C,Dashboard!E10) -> 0 | M10: =SUMIFS('2026'!O:O,'2026'!C:C,Dashboard!E10) -> 2903.43 | N10: =SUMIFS('2026'!I:I,'2026'!C:C,Dashboard!E10) -> 787.45 | O10: =SUMIFS('2026'!J:J,'2026'!C:C,Dashboard!E10) -> 194.02 | P10: =SUMIFS('2026'!L:L,'2026'!C:C,Dashboard!E10) -> 263.89 | Q10: =SUMIFS('2026'!M:M,'2026'!C:C,Dashboard!E10) -> 2480.39
A11: NL | B11: =SUM(INDEX('2026'!$E$2:$Q$938,,MATCH(A11,'2026'!$E$1:$Q$1,0))) -> 2146.05 | E11: TOTAL | F11: =SUM(F4:F10) -> 2899.31 | G11: =SUM(G4:G10) -> 104.58 | H11: =SUM(H4:H10) -> 91.21 | I11: =SUM(I4:I10) -> 1178.21 | J11: =SUM(J4:J10) -> 2937.73 | K11: =SUM(K4:K10) -> 10450.78 | L11: =SUM(L4:L10) -> 2146.05 | M11: =SUM(M4:M10) -> 3063.39 | ... Q11: =SUM(Q4:Q10) -> 2480.39
A12: NW | B12: =SUM(INDEX('2026'!$E$2:$Q$938,,MATCH(A12,'2026'!$E$1:$Q$1,0))) -> 3063.39
A13: PL | B13: =SUM(INDEX('2026'!$E$2:$Q$938,,MATCH(A13,'2026'!$E$1:$Q$1,0))) -> 12318.45
A14: PT | B14: =SUM(INDEX('2026'!$E$2:$Q$938,,MATCH(A14,'2026'!$E$1:$Q$1,0))) -> 194.02
A15: SL | B15: =SUM(INDEX('2026'!$E$2:$Q$938,,MATCH(A15,'2026'!$E$1:$Q$1,0))) -> 11422.71
A16: SV | B16: =SUM(INDEX('2026'!$E$2:$Q$938,,MATCH(A16,'2026'!$E$1:$Q$1,0))) -> 2480.39

Sheet 2026
A1: Datum | B1: Aufrag/Rechnung | C1: Bereich | D1: Typ | E1: EN | F1: IT | G1: ES | H1: NL | I1: PL | J1: PT | K1: CZ | L1: SL | M1: SV | N1: FI | O1: NW | P1: DA | Q1: GR | R1: Übersetzer | S1: TOTAL
A2: 46030 | B2: Rechnung Nr. 2602 | C2: Channel Sales | D2: Verschieden Aufträge (Dezember) | F2: 778.55 | R2: Cristina Firriolo
A3: 46064 | B3: Rechnung Nr. 2605 | C3: Channel Sales | D3: Verschieden Aufträge (Januar) | F3: 275.74 | R3: Cristina Firriolo
A4: 46064 | B4: Rechnung Nr. 2606 | C4: D2C Ecommerce | D4: Verschieden Aufträge Laura Bonfanti (Januar) | F4: 53.39 | R4: Cristina Firriolo
A5: 46064 | B5: Rechnung Nr. 2607 | C5: D2C Ecommerce | D5: Verschieden Aufträge Martine Schmidt (Januar) | F5: 268.83 | R5: Cristina Firriolo
A6: 46064 | B6: Rechnung Nr. 2608 | C6: D2C Ecommerce | D6: Verschieden Aufträge Franziska Schaare (Januar) | F6: 682.67 | R6: Cristina Firriolo
A7: 46064 | B7: Rechnung Nr. 2610 | C7: Technical Communication | D7: FRITZ!Fon Data Act- | F7: 30.36 | R7: Cristina Firriolo
A8: 46086 | B8: Rechnung Nr. 2611 | C8: D2C Ecommerce | D8: D2C | F8: 103.05 | R8: Cristina Firriolo
A9: 46086 | B9: Rechnung Nr. 2612 | C9: D2C Ecommerce | D9: shopify | F9: 165.17 | R9: Cristina Firriolo
A10: 46086 | B10: Rechnung Nr. 2613 | C10: Channel Sales | D10: Vertrieb (BP, PA) | F10: 946.75 | R10: Cristina Firriolo
A11: 46125 | B11: Rechnung Nr. 2614 | C11: D2C Ecommerce | D11: Vertrieb (BP,shopify) | F11: 632.69 | R11: Cristina Firriolo
A12: 46125 | B12: Rechnung Nr. 2615 | C12: Channel Sales | D12: Vertrieb (BP,shopify) | F12: 1280.34 | R12: Cristina Firriolo
A13: 46050 | B13: Rechnung 1-04064 | C13: User Interface & Clients | D13: FRl177_2601_KS_FRITZ!App Smart Horne für iOS: de =>sl | L13: 69.02 | R13: Yabylon
A14: 46050 | B14: Rechnung 1-04065 | C14: User Interface & Clients | D14: FRl177_2601_KS_FRITZ!App Smart Horne für OS: de => pl | I14: 69.02 | R14: Yabylon
A15: 46050 | B15: Rechnung 1-04066 | C15: Technical Communication | D15: FRI178_2601_KS_Data-Act-Text für FRITZ!Smart-Geräte: de => fi | N15: 66.49 | R15: Yabylon
A16: 46050 | B16: Rechnung 1-04067 | C16: Technical Communication | D16: FRI178_2601_KS_Data-Act-Text für FRITZ!Smart-Geräte: de => se | M16: 66.49 | R16: Yabylon
A17: 46050 | B17: Rechnung 1-04068 | C17: Technical Communication | D17: FRI178_2601_KS_Data-Act-Text für FRITZ!Smart-Geräte: de =>no | O17: 66.49 | R17: Yabylon
A18: 46050 | B18: Rechnung 1-04069 | C18: Technical Communication | D18: FRI178_2601_KS_Data-Act-Text für FRITZ!Smart-Geräte: de => pl | I18: 35.82 | R18: Yabylon
A19: 46050 | B19: Rechnung 1-04070 | C19: Technical Communication | D19: FRI178_2601_KS_Data-Act-Text für FRITZ!Smart-Geräte: de => sl | L19: 36.7 | R19: Yabylon
A20: 46050 | B20: Rechnung 1-04071 | C20: Technical Communication | D20: FRI178_2601_KS_Data-Act-Text für FRITZ!Smart-Geräte: de => dk | P20: 63.55 | R20: Yabylon
A21: 46050 | B21: Rechnung 1-04072 | C21: User Interface & Clients | D21: FRl179_2601_KS_MyFRITZ!App für Android: de =>pl | I21: 469.57 | R21: Yabylon
A22: 46050 | B22: Rechnung 1-04073 | C22: User Interface & Clients | D22: FRl179_2601_KS_MyFRITZ!App für Android: de=>sl | L22: 483.54 | R22: Yabylon
A23: 46050 | B23: Rechnung 1-04074 | C23: D2C Ecommerce | D23: FRI180_2601_KS_Amazon-Texte: de => pl | I23: 430.24 | R23: Yabylon
A24: 46050 | B24: Rechnung 1-04075 | C24: User Interface & Clients | D24: FRl181_2601_KS_Neue MyFRITZ!App für iOS: de=> pi | I24: 517.28 | R24: Yabylon
A25: 46050 | B25: Rechnung 1-04076 | C25: User Interface & Clients | D25: FRl181_2601_KS_Neue MyFRITZ!App für OS: de => sl | L25: 517.03 | R25: Yabylon
A26: 46052 | B26: Rechnung 1-04096 | C26: User Interface & Clients | D26: FRI183_2601_KS_Autoresponder: de => pl | I26: 34.51 | R26: Yabylon
A27: 46052 | B27: Rechnung 1-04092 | C27: Technical Communication | D27: FRl174_2512_KS_Kurzanleitungen ins Dänische | P27: 1985.63 | R27: Yabylon
A28: 46052 | B28: Rechnung 1-04093 | C28: Technical Communication | D28: FRl174_2512_KS_Kurzanleitungen ins Finnische | N28: 2055.87 | R28: Yabylon
A29: 46052 | B29: Rechnung 1-04094 | C29: Technical Communication | D29: FRl174_2512_KS_Kurzanleitungen ins Norwegische | O29: 2082.79 | R29: Yabylon
A30: 46052 | B30: Rechnung 1-04095 | C30: Technical Communication | D30: FRl174_2512_KS_Kurzanleitungen ins Schwedische | M30: 1851.13 | R30: Yabylon
A31: 46052 | B31: Rechnung I-04101 | C31: Channel Sales | D31: FRi 182_2601_TK_Mail-Datenlöschung_de-pl | I31: 69.02 | R31: Yabylon
A32: 46073 | B32: Rechnung I-04112 | C32: Technical Communication | D32: FRI184_2601_KS_Data-Act-Texte_de-no | O32: 295.69 | R32: Yabylon
A33: 46073 | B33: Rechnung I-04113 | C33: Technical Communication | D33: FRI184_2601_KS_Data-Act-Texte_de-sv | M33: 295.44 | R33: Yabylon
A34: 46073 | B34: Rechnung I-04114 | C34: Technical Communication | D34: FRI184_2601_KS_Data-Act-Texte_de-da | P34: 281.67 | R34: Yabylon
A35: 46073 | B35: Rechnung I-04115 | C35: Technical Communication | D35: FRI184_2601_KS_Data-Act-Texte_de-fi | N35: 295.44 | R35: Yabylon
A36: 46073 | B36: Rechnung I-04116 | C36: D2C Ecommerce | D36: FRI185_2601_KS_Amazon-Texte - Polnisch | I36: 367.78 | R36: Yabylon
A37: 46073 | B37: Rechnung I-04117 | C37: D2C Ecommerce | D37: FRl186_2601_KS_Mails für den Online-Shop: de => da | P37: 152.8 | R37: Yabylon
A38: 46073 | B38: Rechnung I-04118 | C38: D2C Ecommerce | D38: FRl186_2601_KS_Mails für den Online-Shop: de =>pl | I38: 125.28 | R38: Yabylon
A39: 46073 | B39: Rechnung I-04119 | C39: D2C Ecommerce | D39: FRl186_2601_KS_Mails für den Online-Shop: de => fi | N39: 159.54 | R39: Yabylon
A40: 46073 | B40: Rechnung I-04120 | C40: D2C Ecommerce | D40: FRl186_2601_KS_Mails für den Online-Shop: de => no | O40: 159.96 | R40: Yabylon
...

Sheet 2025
A1: Datum | B1: Abteilung | C1: Aufrag/Rechnung | D1: Typ | E1: EN | F1: IT | G1: ES | H1: NL | I1: PL | J1: PT | K1: CZ | L1: SL | M1: Übersetzer | N1: TOTAL
A2: 45681 | B2: User Interface & Clients | C2: Rechnung I-03309 | D2: FRITZ!App Smart Home für iOS: de => pl | I2: 276.76 | M2: Yabylon
A3: 45681 | B3: User Interface & Clients | C3: Rechnung I-03310 | D3: Neue FRITZ!App Smart Home für Android in PL | I3: 223.93 | M3: Yabylon
A4: 45681 | B4: User Interface & Clients | C4: Rechnung I-03311 | D4: AVM994_2501_KS_1. Runde alte FB-GUI: de => pl | I4: 138.87 | M4: Yabylon
A5: 45681 | B5: User Interface & Clients | C5: Rechnung I-03312 | D5: AVM995_2501_KS_4 Strings für die alte GUI: de | I5: 34.51 | M5: Yabylon
A6: 45681 | B6: Technical Communication | C6: Rechnung I-03313 | D6: KS_INDD_Mesh Set 3000_de-pt | J6: 97.95 | M6: Yabylon
A7: 45681 | C7: Rechnung I-03314 | D7: KS_Produktankündigung FRITZ!Mesh (Wi-Fi) Set 4200: de => pl | I7: 94.33 | M7: Yabylon
A8: 45681 | B8: User Interface & Clients | C8: Rechnung I-03315 | D8: MyFRITZ!App für iOS: de => pl | I8: 515.66 | M8: Yabylon
A9: 45681 | C9: Rechnung I-03316 | D9: Texte_Kurzanleitung_6850_4G_de-pl | I9: 34.51 | M9: Yabylon
A10: 45728 | C10: Rechnung I-03415 | D10: 6860 5G Datensaetze und Product Features_Teil2 DE-PL | I10: 34.51 | M10: Yabylon
A11: 45728 | B11: User Interface & Clients | C11: Rechnung I-03416 | D11: FRITZIApp-Library für Android: de =>pl | I11: 480.69 | M11: Yabylon
A12: 45728 | B12: User Interface & Clients | C12: Rechnung I-03417 | D12: FRITZIApp-Library für Android: de =>pl | I12: 69.02 | M12: Yabylon
A13: 45728 | B13: User Interface & Clients | C13: Rechnung I-03418 | D13: FRITZ!App Smart Horne für OS: de => pl | I13: 64.01 | M13: Yabylon
A14: 45728 | C14: Rechnung I-03419 | D14: KS_Produktvideos_de-pi | I14: 106.35 | M14: Yabylon
A15: 45728 | B15: User Interface & Clients | C15: Rechnung 1-03420 | D15: GUI-index_sl+pl | L15: 69.02 | M15: Yabylon
A16: 45728 | B16: User Interface & Clients | C16: Rechnung I-03421 | D16: Neue MyFRITZIApp: de => pl | I16: 480.15 | M16: Yabylon
A17: 45728 | C17: Rechnung 1-03422 | D17: Produktvideo_6860_5G-de-pl | I17: 35.7 | M17: Yabylon
A18: 45728 | B18: User Interface & Clients | C18: Rechnung 1-03423 | D18: KS_Neue FRITZ!App Smart Horne für Android | I18: 268.96 | M18: Yabylon
A19: 45728 | C19: Rechnung I-03424 | D19: Präambel der Datenschutzerklärung | I19: 34.51 | M19: Yabylon
A20: 45728 | B20: User Interface & Clients | C20: Rechnung I-03425 | D20: GUI SL | L20: 69.02 | M20: Yabylon
A21: 45728 | C21: Rechnung 1-03426 | D21: One_Pager_Kapitel_6860_5G_de-pl | I21: 34.51 | M21: Yabylon
A22: 45747 | C22: Rechnung 1-03437 | D22: RSS024_2503_KS_Über FRITZ!: | I22: 34.51 | M22: Yabylon
A23: 45747 | B23: User Interface & Clients | C23: Rechnung 1-03438 | D23: 1. Runde FRITZ!Box GUI (JS3): | L23: 1375.22 | M23: Yabylon
A24: 45747 | C24: Rechnung 1-03439 | D24: KS_One_Pager_MyFRITZ!_5_Dateien_de-pi | I24: 175.36 | M24: Yabylon
A25: 45747 | B25: Technical Communication | C25: Rechnung 1-03440 | D25: Kurzanleitung_Mesh_Set_4200_de-pt | J25: 123.14 | M25: Yabylon
A26: 45747 | B26: Technical Communication | C26: Rechnung 1-03450 | D26: ritz!Box_6690_HB_de-cz | K26: 6242.63 | M26: Yabylon
A27: 45749 | C27: Rechnung 1-03464 | D27: Produktvideo_6860_5G_de-pl | I27: 34.51 | M27: Yabylon
A28: 45772 | B28: User Interface & Clients | C28: Rechnung 1-03475 | D28: KS_FRITZ!App Smart Horne für Android: de => pl | I28: 340.34 | M28: Yabylon
A29: 45772 | B29: User Interface & Clients | C29: Rechnung 1-03478 | D29: KS_MyFRITZ!App für Android: de => pl | I29: 409.32 | M29: Yabylon
A30: 45772 | B30: User Interface & Clients | C30: Rechnung 1-03476 | D30: KS_2. Runde FRITZ!Box GUI (JS3): de => pl, de => sl | I30: 431.66 | M30: Yabylon
A31: 45772 | B31: User Interface & Clients | C31: Rechnung 1-03477 | D31: KS_FRITZ!App-Library für Android: de => pl | I31: 225.09 | M31: Yabylon
A32: 45772 | C32: Rechnung 1-03479 | D32: KS_FDECT-Umbenennung_de-pl | I32: 34.51 | M32: Yabylon
A33: 45772 | C33: Rechnung 1-03489 | D33: TK_Artikel_3Gruende-Glasfaser_de-pl | I33: 62.68 | M33: Yabylon
A34: 45772 | B34: Technical Communication | C34: Rechnung 1-03490 | D34: TK_Booklet-Repeater2700_de-pt | J34: 71.76 | M34: Yabylon
A35: 45772 | C35: Rechnung I-03491 | D35: Produktankündigung-FRITZIMeshSet-1600_de-pl | I35: 72.51 | M35: Yabylon
A36: 45772 | C36: Rechnung 1-03488 | D36: TK_FRITZ! Box 5690_de-pl | I36: 117.11 | M36: Yabylon
A37: 45772 | B37: User Interface & Clients | C37: Rechnung 1-03480 | D37: KS_3. Runde FRITZ!Box GUI (JS3): de => pl, de => sl | I37: 263.37 | M37: Yabylon
A38: 45772 | B38: Technical Communication | C38: Rechnung 1-03492 | D38: TK_Fritz!Box_6690_Variablen_de-cz | M38: Yabylon
A39: 45772 | B39: Technical Communication | C39: Rechnung 1-03492 | D39: TK_Fritz!Box_6690_Variablen_de-cz | K39: 39.71 | M39: Yabylon
A40: 45799 | B40: Technical Communication | C40: Rechnung 1-03543 | D40: Handbuch_6690_man_de-pi | I40: 4695.95 | M40: Yabylon
...

Sheet ÜM
A1: Datum | B1: Abteilung | C1: Aufrag/Rechnung | D1: Typ | E1: EN | F1: IT | G1: ES | H1: NL | I1: PL | J1: PT | K1: SL | L1: Übersetzer | M1: TOTAL
A2: 45388 | B2: KOM-Übersetzungsmanegment | C2: Rechnung RE1176 | D2: Partner Portal | H2: 489.28 | L2: Marion Caris
A3: 45504 | B3: KOM-Übersetzungsmanegment | C3: Rechnung RE1203 | D3: Partner Portal | H3: 2173.25 | L3: Marion Caris
A4: 45535 | B4: KOM-Übersetzungsmanegment | C4: Rechnung RE1215 | D4: GUI | H4: 28.46 | L4: Marion Caris
A5: 45595 | B5: KOM-Übersetzungsmanegment | C5: Rechnung RE1227 | D5: Produktankündigung | H5: 96.09 | L5: Marion Caris
A6: 45300 | B6: KOM-Übersetzungsmanegment | C6: Rechnung Nr. 2402 | D6: Partner Portal | F6: 182.17 | L6: Cristina Firriolo
A7: 45300 | B7: KOM-Übersetzungsmanegment | C7: Rechnung Nr. 2403 | D7: Produktankündigung | F7: 146.86 | L7: Cristina Firriolo
A8: 45335 | B8: KOM-Übersetzungsmanegment | C8: Rechnung Nr. 2407 | D8: Partner Portal | F8: 287.57 | L8: Cristina Firriolo
A9: 45335 | B9: KOM-Übersetzungsmanegment | C9: Rechnung Nr. 2408 | D9: Partner Portal | F9: 42.88 | L9: Cristina Firriolo
A10: 45362 | B10: KOM-Übersetzungsmanegment | C10: Rechnung Nr. 2412 | D10: Partner Portal und Produktankündigung | F10: 179.89 | L10: Cristina Firriolo
A11: 45384 | B11: KOM-Übersetzungsmanegment | C11: Rechnung Nr. 2417 | D11: Partner Portal | F11: 817.42 | L11: Cristina Firriolo
A12: 45454 | B12: KOM-Übersetzungsmanegment | C12: Rechnung Nr. 2429 | D12: Partner Portal | F12: 209.03 | L12: Cristina Firriolo
A13: 45454 | B13: KOM-Übersetzungsmanegment | C13: Rechnung Nr. 2430 | D13: Partner Portal | F13: 33.49 | L13: Cristina Firriolo
A14: 45478 | B14: KOM-Übersetzungsmanegment | C14: Rechnung Nr. 2435 | D14: Partner Portal | F14: 23.4 | L14: Cristina Firriolo
A15: 45478 | B15: KOM-Übersetzungsmanegment | C15: Rechnung Nr. 2434 | D15: Partner Portal | F15: 153.35 | L15: Cristina Firriolo
A16: 45510 | B16: KOM-Übersetzungsmanegment | C16: Rechnung Nr. 2437 | D16: Partner Portal | F16: 71.13 | L16: Cristina Firriolo
A17: 45512 | B17: KOM-Übersetzungsmanegment | C17: Rechnung Nr. 2439 | D17: Partner Portal und Produktankündigung | F17: 515.07 | L17: Cristina Firriolo
... A24: 45629 | B24: KOM-Übersetzungsmanegment | C24: Rechnung Nr. 2456 | D24: Partner Portal | F24: 78.15 | L24: Cristina Firriolo
A25: 45474 | B25: KOM-Übersetzungsmanegment | C25: Rechnung Nr. 2024-00038 | D25: AVM Webseite | G25: 204.1 | L25: Marta Vicario
A26: 45369 | B26: KOM-Übersetzungsmanegment | C26: Rechnung Nr. AVM-0324-01 | D26: Partner Portal | E26: 145.18 | L26: Kate Simmons
A27: 45320 | B27: KOM-Übersetzungsmanegment | C27: Rechnung I-02630 | D27: GUI | I27: 1058.52 | L27: Yabylon
A28: 45320 | B28: KOM-Übersetzungsmanegment | C28: Rechnung I-02633 | D28: Apps | I28: 836.01 | L28: Yabylon
A29: 45320 | B29: KOM-Übersetzungsmanegment | C29: Rechnung I-02636 | D29: GUI | I29: 69.02 | L29: Yabylon
A30: 45322 | B30: KOM-Übersetzungsmanegment | C30: Rechnung I-02655 | D30: Apps | I30: 278.89 | L30: Yabylon
A31: 45345 | B31: KOM-Übersetzungsmanegment | C31: Rechnung I-02665 | D31: Apps | I31: 513.7 | L31: Yabylon
A32: 45345 | B32: KOM-Übersetzungsmanegment | C32: Rechnung I-02666 | D32: Apps | I32: 69.02 | L32: Yabylon
A33: 45345 | B33: KOM-Übersetzungsmanegment | C33: Rechnung I-02667 | D33: Apps | I33: 203.06 | L33: Yabylon
A34: 45345 | B34: KOM-Übersetzungsmanegment | C34: Rechnung I-02669 | D34: KA | J34: 34.51 | L34: Yabylon
A35: 45345 | B35: KOM-Übersetzungsmanegment | C35: Rechnung I-02670 | D35: Rechtliche Hinweise | I35: 76.4 | L35: Yabylon
A36: 45345 | B36: KOM-Übersetzungsmanegment | C36: Rechnung I-02671 | D36: AVM Webseite | I36: 72.22 | L36: Yabylon
A37: 45345 | B37: KOM-Übersetzungsmanegment | C37: Rechnung I-02697 | D37: AVM Webseite | I37: 70.16 | L37: Yabylon
A38: 45351 | B38: KOM-Übersetzungsmanegment | C38: Rechnung I-02698 | D38: Apps | I38: 358.25 | L38: Yabylon
A39: 45351 | B39: KOM-Übersetzungsmanegment | C39: Rechnung I-02704 | D39: Apps | I39: 201.82 | L39: Yabylon
A40: 45351 | B40: KOM-Übersetzungsmanegment | C40: Rechnung I-02705 | D40: GUI | I40: 69.02 | L40: Yabylon
A41: 45376 | B41: KOM-Übersetzungsmanegment | C41: Rechnung I-02711 | D41: KA Repeater 600 | J41: 69.02 | L41: Yabylon
A42: 45376 | B42: KOM-Übersetzungsmanegment | C42: Rechnung I-02712 | D42: Apps | I42: 76.66 | L42: Yabylon
A43: 45376 | B43: KOM-Übersetzungsmanegment | C43: Rechnung I-02715 | D43: Apps | I43: 215.37 | L43: Yabylon
A44: 45376 | B44: KOM-Übersetzungsmanegment | C44: Rechnung I-02717 | D44: GUI | I44: 34.51 | L44: Yabylon
A45: 45379 | B45: KOM-Übersetzungsmanegment | C45: Rechnung I-02729 | D45: Produkankündigung | I45: 92.88 | L45: Yabylon
A46: 45406 | B46: KOM-Übersetzungsmanegment | C46: Rechnung I-02759 | D46: GUI | I46: 1617.59 | L46: Yabylon
...

Sheet Online
A1: Datum | B1: Abteilung | C1: Aufrag/Rechnung | D1: Typ | E1: EN | F1: IT | G1: ES | H1: NL | I1: PL | J1: PT | K1: SL | L1: Übersetzer | M1: TOTAL
A2: 45323 | B2: KOM-Online | C2: Rechnung RE1145 | D2: AVM Webseite | H2: 205.43 | L2: Marion Caris
A3: 45355 | B3: KOM-Online | C3: Rechnung RE1161 | D3: AVM Webseite | H3: 160.84 | L3: Marion Caris
A4: 45384 | B4: KOM-Online | C4: Rechnung RE1167 | D4: AVM Webseite | H4: 772.74 | L4: Marion Caris
A5: 45408 | B5: KOM-Online | C5: Rechnung RE1179 | D5: AVM Webseite | H5: 367.63 | L5: Marion Caris
A6: 45442 | B6: KOM-Online | C6: Rechnung RE1187 | D6: AVM Webseite | H6: 415.73 | L6: Marion Caris
A7: 45474 | B7: KOM-Online | C7: Rechnung RE1192 | D7: AVM Webseite | H7: 193.78 | L7: Marion Caris
A8: 45535 | B8: KOM-Online | C8: Rechnung RE1216 | D8: AVM Webseite | H8: 323.87 | L8: Marion Caris
A9: 45566 | B9: KOM-Online | C9: Rechnung RE1219 | D9: Pressemitteilung | H9: 96.21 | L9: Marion Caris
A10: 45566 | B10: KOM-Online | C10: Rechnung RE1218 | D10: AVM Webseite | H10: 200.73 | L10: Marion Caris
A11: 45595 | B11: KOM-Online | C11: Rechnung RE1228 | D11: AVM Webseite | H11: 349.44 | L11: Marion Caris
A12: 45623 | B12: KOM-Online | C12: Rechnung RE1242 | D12: AVM Webseite | H12: 366.29 | L12: Marion Caris
A13: 45446 | B13: KOM-Online | C13: Rechnung R240308 | D13: AVM Webseite | E13: 673.66 | L13: English Rose
A14: 45572 | B14: KOM-Online | C14: Rechnung R240318 | E14: 910.35 | L14: English Rose
A15: 45300 | B15: KOM-Online | C15: Rechnung Nr. 2401 | D15: AVM Webseite | F15: 170.51 | L15: Cristina Firriolo
A16: 45335 | B16: KOM-Online | C16: Rechnung Nr. 2406 | D16: AVM Webseite | F16: 306.23 | L16: Cristina Firriolo
A17: 45362 | B17: KOM-Online | C17: Rechnung Nr. 2413 | D17: AVM Webseite | F17: 612.68 | L17: Cristina Firriolo
A18: 45384 | B18: KOM-Online | C18: Rechnung Nr. 2418 | D18: AVM Webseite | F18: 400.91 | L18: Cristina Firriolo
A19: 45454 | B19: KOM-Online | C19: Rechnung Nr. 2428 | D19: AVM Webseite | F19: 293.02 | L19: Cristina Firriolo
A20: 45478 | B20: KOM-Online | C20: Rechnung Nr. 2433 | D20: AVM Webseite | F20: 201.3 | L20: Cristina Firriolo
A21: 45509 | B21: KOM-Online | C21: Rechnung Nr. 2438 | D21: AVM Webseite | F21: 1176.62 | L21: Cristina Firriolo
A22: 45545 | B22: KOM-Online | C22: Rechnung Nr. 2442 | D22: AVM Webseite | F22: 754.72 | L22: Cristina Firriolo
A23: 45572 | B23: KOM-Online | C23: Rechnung Nr. 2444 | D23: FRITZ!Folder | F23: 35.48 | L23: Cristina Firriolo
A24: 45572 | B24: KOM-Online | C24: Rechnung Nr. 2445 | D24: AVM Webseite | F24: 199.09 | L24: Cristina Firriolo
A25: 45607 | B25: KOM-Online | C25: Rechnung Nr. 2449 | D25: AVM Webseite | F25: 333.03 | L25: Cristina Firriolo
A26: 45629 | B26: KOM-Online | C26: Rechnung Nr. 2455 | D26: AVM Webseite | F26: 196.94 | L26: Cristina Firriolo
A27: 45434 | B27: KOM-Online | C27: Rechnungsnummer 565 | D27: Richtlinie Kartellrecht | E27: 691.88 | L27: Tyler Langendorfer
A28: 45440 | B28: KOM-Online | C28: Rechnung Nr. 2024-00029 | D28: AVM Webseite | G28: 703.69 | L28: Marta Vicario
A29: 45320 | B29: KOM-Online | C29: Rechnung I-02631 | D29: AVM Webseite | I29: 34.51 | L29: Yabylon
A30: 45320 | B30: KOM-Online | C30: Rechnung I-02632 | D30: AVM Webseite | I30: 34.51 | L30: Yabylon
A31: 45320 | B31: KOM-Online | C31: Rechnung I-02634 | D31: AVM Webseite | I31: 136.98 | L31: Yabylon
A32: 45320 | B32: KOM-Online | C32: Rechnung I-02635 | D32: AVM Webseite | I32: 78.37 | L32: Yabylon
A33: 45322 | B33: KOM-Online | C33: Rechnung I-02656 | D33: AVM Webseite | I33: 69.02 | L33: Yabylon
A34: 45345 | B34: KOM-Online | C34: Rechnung I-02664 | D34: AVM Webseite | I34: 171.66 | L34: Yabylon
A35: 45345 | B35: KOM-Online | C35: Rechnung I-02668 | D35: AVM Webseite | I35: 34.51 | L35: Yabylon
A36: 45351 | B36: KOM-Online | C36: Rechnung I-02701 | D36: AVM Webseite | I36: 69.02 | L36: Yabylon
A37: 45351 | B37: KOM-Online | C37: Rechnung I-02702 | D37: AVM Webseite | I37: 69.02 | L37: Yabylon
A38: 45351 | B38: KOM-Online | C38: Rechnung I-02703 | D38: AVM Webseite | I38: 96.91 | L38: Yabylon
A39: 45351 | B39: KOM-Online | C39: Rechnung I-02706 | D39: AVM Webseite | I39: 69.02 | L39: Yabylon
A40: 45376 | B40: KOM-Online | C40: Rechnung I-02713 | D40: AVM Webseite | I40: 88.1 | L40: Yabylon
...

Sheet Alles
A1: Datum | B1: Abteilung | C1: Aufrag/Rechnung | D1: Typ | E1: EN | F1: IT | G1: ES | H1: NL | I1: PL | J1: PT | K1: SL | L1: Übersetzer | M1: TOTAL
A2: 45323 | B2: KOM-Online | C2: Rechnung RE1145 | D2: AVM Webseite | H2: 205.43 | L2: Marion Caris
A3: 45355 | B3: KOM-Online | C3: Rechnung RE1161 | D3: AVM Webseite | H3: 160.84 | L3: Marion Caris
A4: 45384 | B4: KOM-Online | C4: Rechnung RE1167 | D4: AVM Webseite | H4: 772.74 | L4: Marion Caris
A5: 45388 | B5: KOM-Übersetzungsmanegment | C5: Rechnung RE1176 | D5: Partner Portal | H5: 489.28 | L5: Marion Caris
A6: 45408 | B6: KOM-Online | C6: Rechnung RE1179 | D6: AVM Webseite | H6: 367.63 | L6: Marion Caris
A7: 45442 | B7: KOM-Online | C7: Rechnung RE1187 | D7: AVM Webseite | H7: 415.73 | L7: Marion Caris
A8: 45474 | B8: KOM-Online | C8: Rechnung RE1192 | D8: AVM Webseite | H8: 193.78 | L8: Marion Caris
A9: 45504 | B9: KOM-Übersetzungsmanegment | C9: Rechnung RE1203 | D9: Partner Portal | H9: 2173.25 | L9: Marion Caris
A10: 45535 | B10: KOM-Übersetzungsmanegment | C10: Rechnung RE1215 | D10: GUI | H10: 28.46 | L10: Marion Caris
A11: 45535 | B11: KOM-Online | C11: Rechnung RE1216 | D11: AVM Webseite | H11: 323.87 | L11: Marion Caris
A12: 45566 | B12: KOM-Online | C12: Rechnung RE1219 | D12: Pressemitteilung | H12: 96.21 | L12: Marion Caris
A13: 45566 | B13: KOM-Online | C13: Rechnung RE1218 | D13: AVM Webseite | H13: 200.73 | L13: Marion Caris
... A16: 45623 | B16: KOM-Online | C16: Rechnung RE1242 | D16: AVM Webseite | H16: 366.29 | L16: Marion Caris
A17: 45446 | B17: KOM-Online | C17: Rechnung R240308 | D17: AVM Webseite | E17: 673.66 | L17: English Rose
A18: 45572 | B18: KOM-Online | C18: Rechnung R240318 | E18: 910.35 | L18: English Rose
A19: 45300 | B19: KOM-Online | C19: Rechnung Nr. 2401 | D19: AVM Webseite | F19: 170.51 | L19: Cristina Firriolo
A20: 45300 | B20: KOM-Übersetzungsmanegment | C20: Rechnung Nr. 2402 | D20: Partner Portal | F20: 182.17 | L20: Cristina Firriolo
A21: 45300 | B21: KOM-Übersetzungsmanegment | C21: Rechnung Nr. 2403 | D21: Produktankündigung | F21: 146.86 | L21: Cristina Firriolo
A22: 45335 | B22: KOM-Online | C22: Rechnung Nr. 2406 | D22: AVM Webseite | F22: 306.23 | L22: Cristina Firriolo
A23: 45335 | B23: KOM-Übersetzungsmanegment | C23: Rechnung Nr. 2407 | D23: Partner Portal | F23: 287.57 | L23: Cristina Firriolo
A24: 45335 | B24: KOM-Übersetzungsmanegment | C24: Rechnung Nr. 2408 | D24: Partner Portal | F24: 42.88 | L24: Cristina Firriolo
A25: 45362 | B25: KOM-Übersetzungsmanegment | C25: Rechnung Nr. 2412 | D25: Partner Portal und Produktankündigung | F25: 179.89 | L25: Cristina Firriolo
A26: 45362 | B26: KOM-Online | C26: Rechnung Nr. 2413 | D26: AVM Webseite | F26: 612.68 | L26: Cristina Firriolo
A27: 45384 | B27: KOM-Übersetzungsmanegment | C27: Rechnung Nr. 2417 | D27: Partner Portal | F27: 817.42 | L27: Cristina Firriolo
A28: 45384 | B28: KOM-Online | C28: Rechnung Nr. 2418 | D28: AVM Webseite | F28: 400.91 | L28: Cristina Firriolo
A29: 45454 | B29: KOM-Online | C29: Rechnung Nr. 2428 | D29: AVM Webseite | F29: 293.02 | L29: Cristina Firriolo
A30: 45454 | B30: KOM-Übersetzungsmanegment | C30: Rechnung Nr. 2429 | D30: Partner Portal | F30: 209.03 | L30: Cristina Firriolo
... A49: 45629 | B49: KOM-Übersetzungsmanegment | C49: Rechnung Nr. 2456 | D49: Partner Portal | F49: 78.15 | L49: Cristina Firriolo
A50: 45434 | B50: KOM-Online | C50: Rechnungsnummer 565 | D50: Richtlinie Kartellrecht | E50: 691.88 | L50: Tyler Langendorfer
A51: 45440 | B51: KOM-Online | C51: Rechnung Nr. 2024-00029 | D51: AVM Webseite | G51: 703.69 | L51: Marta Vicario
A52: 45474 | B52: KOM-Übersetzungsmanegment | C52: Rechnung Nr. 2024-00038 | D52: AVM Webseite | G52: 204.1 | L52: Marta Vicario
A53: 45369 | B53: KOM-Übersetzungsmanegment | C53: Rechnung Nr. AVM-0324-01 | D53: Partner Portal | E53: 145.18 | L53: Kate Simmons
A54: 45320 | B54: KOM-Übersetzungsmanegment | C54: Rechnung I-02630 | D54: GUI | I54: 1058.52 | L54: Yabylon
A55: 45320 | B55: KOM-Online | C55: Rechnung I-02631 | D55: AVM Webseite | I55: 34.51 | L55: Yabylon
A56: 45320 | B56: KOM-Online | C56: Rechnung I-02632 | D56: AVM Webseite | I56: 34.51 | L56: Yabylon
A57: 45320 | B57: KOM-Übersetzungsmanegment | C57: Rechnung I-02633 | D57: Apps | I57: 836.01 | L57: Yabylon
A58: 45320 | B58: KOM-Online | C58: Rechnung I-02634 | D58: AVM Webseite | I58: 136.98 | L58: Yabylon
A59: 45320 | B59: KOM-Online | C59: Rechnung I-02635 | D59: AVM Webseite | I59: 78.37 | L59: Yabylon
A60: 45320 | B60: KOM-Übersetzungsmanegment | C60: Rechnung I-02636 | D60: GUI | I60: 69.02 | L60: Yabylon
...
